[ 2023-12-11 20:20:10,198 ] 96 werkzeug - WARNING -  * Debugger is active!
[ 2023-12-11 20:20:10,206 ] 96 werkzeug - INFO -  * Debugger PIN: 782-199-451
[ 2023-12-11 20:20:17,782 ] 92 root - INFO - Entered initiate_data_ingestion method of Data_Ingestion class
[ 2023-12-11 20:20:17,783 ] 60 root - INFO - Exporting data from mongodb
[ 2023-12-11 20:20:20,788 ] 69 root - INFO - Saving exported data into feature store file path: artifacts
[ 2023-12-11 20:20:20,848 ] 98 root - INFO - Got the data from mongodb
[ 2023-12-11 20:20:20,848 ] 101 root - INFO - Exited initiate_data_ingestion method of Data_Ingestion class
[ 2023-12-11 20:20:20,852 ] 99 root - INFO - Entered initiate_data_transformation method of Data_Transformation class
[ 2023-12-11 20:20:21,012 ] 39 root - INFO - Entered the save_object method of MainUtils class
[ 2023-12-11 20:20:21,013 ] 45 root - INFO - Exited the save_object method of MainUtils class
[ 2023-12-11 20:20:21,014 ] 145 root - INFO - Splitting training and testing input and target feature
[ 2023-12-11 20:20:21,015 ] 156 root - INFO - Extracting model config file path
[ 2023-12-11 20:20:21,015 ] 163 root - INFO - Extracting model config file path
[ 2023-12-11 20:21:21,158 ] 96 werkzeug - INFO -  * Detected change in 'c:\\users\\91985\\desktop\\123\\projects\\ml\\waferfault_detection\\src\\components\\model_trainer.py', reloading
[ 2023-12-11 20:21:21,186 ] 28 concurrent.futures - ERROR - exception calling callback for <Future at 0x1db749dc7f0 state=finished returned list>
Traceback (most recent call last):
  File "c:\Users\91985\Desktop\123\Projects\ML\Waferfault_detection\env\lib\site-packages\joblib\externals\loky\_base.py", line 26, in _invoke_callbacks
    callback(self)
  File "c:\Users\91985\Desktop\123\Projects\ML\Waferfault_detection\env\lib\site-packages\joblib\parallel.py", line 814, in __call__
    self._dispatch_new()
  File "c:\Users\91985\Desktop\123\Projects\ML\Waferfault_detection\env\lib\site-packages\joblib\parallel.py", line 829, in _dispatch_new
    self.parallel.dispatch_next()
  File "c:\Users\91985\Desktop\123\Projects\ML\Waferfault_detection\env\lib\site-packages\joblib\parallel.py", line 1395, in dispatch_next
    if not self.dispatch_one_batch(self._original_iterator):
  File "c:\Users\91985\Desktop\123\Projects\ML\Waferfault_detection\env\lib\site-packages\joblib\parallel.py", line 1462, in dispatch_one_batch
    self._dispatch(tasks)
  File "c:\Users\91985\Desktop\123\Projects\ML\Waferfault_detection\env\lib\site-packages\joblib\parallel.py", line 1384, in _dispatch
    job = self._backend.apply_async(batch, callback=batch_tracker)
  File "c:\Users\91985\Desktop\123\Projects\ML\Waferfault_detection\env\lib\site-packages\joblib\_parallel_backends.py", line 600, in apply_async
    future = self._workers.submit(func)
  File "c:\Users\91985\Desktop\123\Projects\ML\Waferfault_detection\env\lib\site-packages\joblib\externals\loky\reusable_executor.py", line 225, in submit
    return super().submit(fn, *args, **kwargs)
  File "c:\Users\91985\Desktop\123\Projects\ML\Waferfault_detection\env\lib\site-packages\joblib\externals\loky\process_executor.py", line 1228, in submit
    raise ShutdownExecutorError(
joblib.externals.loky.process_executor.ShutdownExecutorError: cannot schedule new futures after shutdown
[ 2023-12-11 20:21:21,377 ] 28 concurrent.futures - ERROR - exception calling callback for <Future at 0x1db7490af70 state=finished returned list>
Traceback (most recent call last):
  File "c:\Users\91985\Desktop\123\Projects\ML\Waferfault_detection\env\lib\site-packages\joblib\externals\loky\_base.py", line 26, in _invoke_callbacks
    callback(self)
  File "c:\Users\91985\Desktop\123\Projects\ML\Waferfault_detection\env\lib\site-packages\joblib\parallel.py", line 814, in __call__
    self._dispatch_new()
  File "c:\Users\91985\Desktop\123\Projects\ML\Waferfault_detection\env\lib\site-packages\joblib\parallel.py", line 829, in _dispatch_new
    self.parallel.dispatch_next()
  File "c:\Users\91985\Desktop\123\Projects\ML\Waferfault_detection\env\lib\site-packages\joblib\parallel.py", line 1395, in dispatch_next
    if not self.dispatch_one_batch(self._original_iterator):
  File "c:\Users\91985\Desktop\123\Projects\ML\Waferfault_detection\env\lib\site-packages\joblib\parallel.py", line 1462, in dispatch_one_batch
    self._dispatch(tasks)
  File "c:\Users\91985\Desktop\123\Projects\ML\Waferfault_detection\env\lib\site-packages\joblib\parallel.py", line 1384, in _dispatch
    job = self._backend.apply_async(batch, callback=batch_tracker)
  File "c:\Users\91985\Desktop\123\Projects\ML\Waferfault_detection\env\lib\site-packages\joblib\_parallel_backends.py", line 600, in apply_async
    future = self._workers.submit(func)
  File "c:\Users\91985\Desktop\123\Projects\ML\Waferfault_detection\env\lib\site-packages\joblib\externals\loky\reusable_executor.py", line 225, in submit
    return super().submit(fn, *args, **kwargs)
  File "c:\Users\91985\Desktop\123\Projects\ML\Waferfault_detection\env\lib\site-packages\joblib\externals\loky\process_executor.py", line 1228, in submit
    raise ShutdownExecutorError(
joblib.externals.loky.process_executor.ShutdownExecutorError: cannot schedule new futures after shutdown
[ 2023-12-11 20:21:21,489 ] 28 concurrent.futures - ERROR - exception calling callback for <Future at 0x1db749dcf10 state=finished returned list>
Traceback (most recent call last):
  File "c:\Users\91985\Desktop\123\Projects\ML\Waferfault_detection\env\lib\site-packages\joblib\externals\loky\_base.py", line 26, in _invoke_callbacks
    callback(self)
  File "c:\Users\91985\Desktop\123\Projects\ML\Waferfault_detection\env\lib\site-packages\joblib\parallel.py", line 814, in __call__
    self._dispatch_new()
  File "c:\Users\91985\Desktop\123\Projects\ML\Waferfault_detection\env\lib\site-packages\joblib\parallel.py", line 829, in _dispatch_new
    self.parallel.dispatch_next()
  File "c:\Users\91985\Desktop\123\Projects\ML\Waferfault_detection\env\lib\site-packages\joblib\parallel.py", line 1395, in dispatch_next
    if not self.dispatch_one_batch(self._original_iterator):
  File "c:\Users\91985\Desktop\123\Projects\ML\Waferfault_detection\env\lib\site-packages\joblib\parallel.py", line 1462, in dispatch_one_batch
    self._dispatch(tasks)
  File "c:\Users\91985\Desktop\123\Projects\ML\Waferfault_detection\env\lib\site-packages\joblib\parallel.py", line 1384, in _dispatch
    job = self._backend.apply_async(batch, callback=batch_tracker)
  File "c:\Users\91985\Desktop\123\Projects\ML\Waferfault_detection\env\lib\site-packages\joblib\_parallel_backends.py", line 600, in apply_async
    future = self._workers.submit(func)
  File "c:\Users\91985\Desktop\123\Projects\ML\Waferfault_detection\env\lib\site-packages\joblib\externals\loky\reusable_executor.py", line 225, in submit
    return super().submit(fn, *args, **kwargs)
  File "c:\Users\91985\Desktop\123\Projects\ML\Waferfault_detection\env\lib\site-packages\joblib\externals\loky\process_executor.py", line 1228, in submit
    raise ShutdownExecutorError(
joblib.externals.loky.process_executor.ShutdownExecutorError: cannot schedule new futures after shutdown
[ 2023-12-11 20:21:21,825 ] 28 concurrent.futures - ERROR - exception calling callback for <Future at 0x1db748163a0 state=finished returned list>
Traceback (most recent call last):
  File "c:\Users\91985\Desktop\123\Projects\ML\Waferfault_detection\env\lib\site-packages\joblib\externals\loky\_base.py", line 26, in _invoke_callbacks
    callback(self)
  File "c:\Users\91985\Desktop\123\Projects\ML\Waferfault_detection\env\lib\site-packages\joblib\parallel.py", line 814, in __call__
    self._dispatch_new()
  File "c:\Users\91985\Desktop\123\Projects\ML\Waferfault_detection\env\lib\site-packages\joblib\parallel.py", line 829, in _dispatch_new
    self.parallel.dispatch_next()
  File "c:\Users\91985\Desktop\123\Projects\ML\Waferfault_detection\env\lib\site-packages\joblib\parallel.py", line 1395, in dispatch_next
    if not self.dispatch_one_batch(self._original_iterator):
  File "c:\Users\91985\Desktop\123\Projects\ML\Waferfault_detection\env\lib\site-packages\joblib\parallel.py", line 1462, in dispatch_one_batch
    self._dispatch(tasks)
  File "c:\Users\91985\Desktop\123\Projects\ML\Waferfault_detection\env\lib\site-packages\joblib\parallel.py", line 1384, in _dispatch
    job = self._backend.apply_async(batch, callback=batch_tracker)
  File "c:\Users\91985\Desktop\123\Projects\ML\Waferfault_detection\env\lib\site-packages\joblib\_parallel_backends.py", line 600, in apply_async
    future = self._workers.submit(func)
  File "c:\Users\91985\Desktop\123\Projects\ML\Waferfault_detection\env\lib\site-packages\joblib\externals\loky\reusable_executor.py", line 225, in submit
    return super().submit(fn, *args, **kwargs)
  File "c:\Users\91985\Desktop\123\Projects\ML\Waferfault_detection\env\lib\site-packages\joblib\externals\loky\process_executor.py", line 1228, in submit
    raise ShutdownExecutorError(
joblib.externals.loky.process_executor.ShutdownExecutorError: cannot schedule new futures after shutdown
[ 2023-12-11 20:21:21,831 ] 28 concurrent.futures - ERROR - exception calling callback for <Future at 0x1db74816fa0 state=finished returned list>
Traceback (most recent call last):
  File "c:\Users\91985\Desktop\123\Projects\ML\Waferfault_detection\env\lib\site-packages\joblib\externals\loky\_base.py", line 26, in _invoke_callbacks
    callback(self)
  File "c:\Users\91985\Desktop\123\Projects\ML\Waferfault_detection\env\lib\site-packages\joblib\parallel.py", line 814, in __call__
    self._dispatch_new()
  File "c:\Users\91985\Desktop\123\Projects\ML\Waferfault_detection\env\lib\site-packages\joblib\parallel.py", line 829, in _dispatch_new
    self.parallel.dispatch_next()
  File "c:\Users\91985\Desktop\123\Projects\ML\Waferfault_detection\env\lib\site-packages\joblib\parallel.py", line 1395, in dispatch_next
    if not self.dispatch_one_batch(self._original_iterator):
  File "c:\Users\91985\Desktop\123\Projects\ML\Waferfault_detection\env\lib\site-packages\joblib\parallel.py", line 1462, in dispatch_one_batch
    self._dispatch(tasks)
  File "c:\Users\91985\Desktop\123\Projects\ML\Waferfault_detection\env\lib\site-packages\joblib\parallel.py", line 1384, in _dispatch
    job = self._backend.apply_async(batch, callback=batch_tracker)
  File "c:\Users\91985\Desktop\123\Projects\ML\Waferfault_detection\env\lib\site-packages\joblib\_parallel_backends.py", line 600, in apply_async
    future = self._workers.submit(func)
  File "c:\Users\91985\Desktop\123\Projects\ML\Waferfault_detection\env\lib\site-packages\joblib\externals\loky\reusable_executor.py", line 225, in submit
    return super().submit(fn, *args, **kwargs)
  File "c:\Users\91985\Desktop\123\Projects\ML\Waferfault_detection\env\lib\site-packages\joblib\externals\loky\process_executor.py", line 1228, in submit
    raise ShutdownExecutorError(
joblib.externals.loky.process_executor.ShutdownExecutorError: cannot schedule new futures after shutdown
[ 2023-12-11 20:21:22,521 ] 28 concurrent.futures - ERROR - exception calling callback for <Future at 0x1db749dc3a0 state=finished returned list>
Traceback (most recent call last):
  File "c:\Users\91985\Desktop\123\Projects\ML\Waferfault_detection\env\lib\site-packages\joblib\externals\loky\_base.py", line 26, in _invoke_callbacks
    callback(self)
  File "c:\Users\91985\Desktop\123\Projects\ML\Waferfault_detection\env\lib\site-packages\joblib\parallel.py", line 814, in __call__
    self._dispatch_new()
  File "c:\Users\91985\Desktop\123\Projects\ML\Waferfault_detection\env\lib\site-packages\joblib\parallel.py", line 829, in _dispatch_new
    self.parallel.dispatch_next()
  File "c:\Users\91985\Desktop\123\Projects\ML\Waferfault_detection\env\lib\site-packages\joblib\parallel.py", line 1395, in dispatch_next
    if not self.dispatch_one_batch(self._original_iterator):
  File "c:\Users\91985\Desktop\123\Projects\ML\Waferfault_detection\env\lib\site-packages\joblib\parallel.py", line 1462, in dispatch_one_batch
    self._dispatch(tasks)
  File "c:\Users\91985\Desktop\123\Projects\ML\Waferfault_detection\env\lib\site-packages\joblib\parallel.py", line 1384, in _dispatch
    job = self._backend.apply_async(batch, callback=batch_tracker)
  File "c:\Users\91985\Desktop\123\Projects\ML\Waferfault_detection\env\lib\site-packages\joblib\_parallel_backends.py", line 600, in apply_async
    future = self._workers.submit(func)
  File "c:\Users\91985\Desktop\123\Projects\ML\Waferfault_detection\env\lib\site-packages\joblib\externals\loky\reusable_executor.py", line 225, in submit
    return super().submit(fn, *args, **kwargs)
  File "c:\Users\91985\Desktop\123\Projects\ML\Waferfault_detection\env\lib\site-packages\joblib\externals\loky\process_executor.py", line 1228, in submit
    raise ShutdownExecutorError(
joblib.externals.loky.process_executor.ShutdownExecutorError: cannot schedule new futures after shutdown
[ 2023-12-11 20:21:22,871 ] 28 concurrent.futures - ERROR - exception calling callback for <Future at 0x1db749dc250 state=finished returned list>
Traceback (most recent call last):
  File "c:\Users\91985\Desktop\123\Projects\ML\Waferfault_detection\env\lib\site-packages\joblib\externals\loky\_base.py", line 26, in _invoke_callbacks
    callback(self)
  File "c:\Users\91985\Desktop\123\Projects\ML\Waferfault_detection\env\lib\site-packages\joblib\parallel.py", line 814, in __call__
    self._dispatch_new()
  File "c:\Users\91985\Desktop\123\Projects\ML\Waferfault_detection\env\lib\site-packages\joblib\parallel.py", line 829, in _dispatch_new
    self.parallel.dispatch_next()
  File "c:\Users\91985\Desktop\123\Projects\ML\Waferfault_detection\env\lib\site-packages\joblib\parallel.py", line 1395, in dispatch_next
    if not self.dispatch_one_batch(self._original_iterator):
  File "c:\Users\91985\Desktop\123\Projects\ML\Waferfault_detection\env\lib\site-packages\joblib\parallel.py", line 1462, in dispatch_one_batch
    self._dispatch(tasks)
  File "c:\Users\91985\Desktop\123\Projects\ML\Waferfault_detection\env\lib\site-packages\joblib\parallel.py", line 1384, in _dispatch
    job = self._backend.apply_async(batch, callback=batch_tracker)
  File "c:\Users\91985\Desktop\123\Projects\ML\Waferfault_detection\env\lib\site-packages\joblib\_parallel_backends.py", line 600, in apply_async
    future = self._workers.submit(func)
  File "c:\Users\91985\Desktop\123\Projects\ML\Waferfault_detection\env\lib\site-packages\joblib\externals\loky\reusable_executor.py", line 225, in submit
    return super().submit(fn, *args, **kwargs)
  File "c:\Users\91985\Desktop\123\Projects\ML\Waferfault_detection\env\lib\site-packages\joblib\externals\loky\process_executor.py", line 1228, in submit
    raise ShutdownExecutorError(
joblib.externals.loky.process_executor.ShutdownExecutorError: cannot schedule new futures after shutdown
[ 2023-12-11 20:21:22,917 ] 28 concurrent.futures - ERROR - exception calling callback for <Future at 0x1db72d32790 state=finished returned list>
Traceback (most recent call last):
  File "c:\Users\91985\Desktop\123\Projects\ML\Waferfault_detection\env\lib\site-packages\joblib\externals\loky\_base.py", line 26, in _invoke_callbacks
    callback(self)
  File "c:\Users\91985\Desktop\123\Projects\ML\Waferfault_detection\env\lib\site-packages\joblib\parallel.py", line 814, in __call__
    self._dispatch_new()
  File "c:\Users\91985\Desktop\123\Projects\ML\Waferfault_detection\env\lib\site-packages\joblib\parallel.py", line 829, in _dispatch_new
    self.parallel.dispatch_next()
  File "c:\Users\91985\Desktop\123\Projects\ML\Waferfault_detection\env\lib\site-packages\joblib\parallel.py", line 1395, in dispatch_next
    if not self.dispatch_one_batch(self._original_iterator):
  File "c:\Users\91985\Desktop\123\Projects\ML\Waferfault_detection\env\lib\site-packages\joblib\parallel.py", line 1462, in dispatch_one_batch
    self._dispatch(tasks)
  File "c:\Users\91985\Desktop\123\Projects\ML\Waferfault_detection\env\lib\site-packages\joblib\parallel.py", line 1384, in _dispatch
    job = self._backend.apply_async(batch, callback=batch_tracker)
  File "c:\Users\91985\Desktop\123\Projects\ML\Waferfault_detection\env\lib\site-packages\joblib\_parallel_backends.py", line 600, in apply_async
    future = self._workers.submit(func)
  File "c:\Users\91985\Desktop\123\Projects\ML\Waferfault_detection\env\lib\site-packages\joblib\externals\loky\reusable_executor.py", line 225, in submit
    return super().submit(fn, *args, **kwargs)
  File "c:\Users\91985\Desktop\123\Projects\ML\Waferfault_detection\env\lib\site-packages\joblib\externals\loky\process_executor.py", line 1228, in submit
    raise ShutdownExecutorError(
joblib.externals.loky.process_executor.ShutdownExecutorError: cannot schedule new futures after shutdown
[ 2023-12-11 20:21:22,934 ] 28 concurrent.futures - ERROR - exception calling callback for <Future at 0x1db74816910 state=finished returned list>
Traceback (most recent call last):
  File "c:\Users\91985\Desktop\123\Projects\ML\Waferfault_detection\env\lib\site-packages\joblib\externals\loky\_base.py", line 26, in _invoke_callbacks
    callback(self)
  File "c:\Users\91985\Desktop\123\Projects\ML\Waferfault_detection\env\lib\site-packages\joblib\parallel.py", line 814, in __call__
    self._dispatch_new()
  File "c:\Users\91985\Desktop\123\Projects\ML\Waferfault_detection\env\lib\site-packages\joblib\parallel.py", line 829, in _dispatch_new
    self.parallel.dispatch_next()
  File "c:\Users\91985\Desktop\123\Projects\ML\Waferfault_detection\env\lib\site-packages\joblib\parallel.py", line 1395, in dispatch_next
    if not self.dispatch_one_batch(self._original_iterator):
  File "c:\Users\91985\Desktop\123\Projects\ML\Waferfault_detection\env\lib\site-packages\joblib\parallel.py", line 1462, in dispatch_one_batch
    self._dispatch(tasks)
  File "c:\Users\91985\Desktop\123\Projects\ML\Waferfault_detection\env\lib\site-packages\joblib\parallel.py", line 1384, in _dispatch
    job = self._backend.apply_async(batch, callback=batch_tracker)
  File "c:\Users\91985\Desktop\123\Projects\ML\Waferfault_detection\env\lib\site-packages\joblib\_parallel_backends.py", line 600, in apply_async
    future = self._workers.submit(func)
  File "c:\Users\91985\Desktop\123\Projects\ML\Waferfault_detection\env\lib\site-packages\joblib\externals\loky\reusable_executor.py", line 225, in submit
    return super().submit(fn, *args, **kwargs)
  File "c:\Users\91985\Desktop\123\Projects\ML\Waferfault_detection\env\lib\site-packages\joblib\externals\loky\process_executor.py", line 1228, in submit
    raise ShutdownExecutorError(
joblib.externals.loky.process_executor.ShutdownExecutorError: cannot schedule new futures after shutdown
[ 2023-12-11 20:21:23,343 ] 28 concurrent.futures - ERROR - exception calling callback for <Future at 0x1db72d32580 state=finished returned list>
Traceback (most recent call last):
  File "c:\Users\91985\Desktop\123\Projects\ML\Waferfault_detection\env\lib\site-packages\joblib\externals\loky\_base.py", line 26, in _invoke_callbacks
    callback(self)
  File "c:\Users\91985\Desktop\123\Projects\ML\Waferfault_detection\env\lib\site-packages\joblib\parallel.py", line 814, in __call__
    self._dispatch_new()
  File "c:\Users\91985\Desktop\123\Projects\ML\Waferfault_detection\env\lib\site-packages\joblib\parallel.py", line 829, in _dispatch_new
    self.parallel.dispatch_next()
  File "c:\Users\91985\Desktop\123\Projects\ML\Waferfault_detection\env\lib\site-packages\joblib\parallel.py", line 1395, in dispatch_next
    if not self.dispatch_one_batch(self._original_iterator):
  File "c:\Users\91985\Desktop\123\Projects\ML\Waferfault_detection\env\lib\site-packages\joblib\parallel.py", line 1462, in dispatch_one_batch
    self._dispatch(tasks)
  File "c:\Users\91985\Desktop\123\Projects\ML\Waferfault_detection\env\lib\site-packages\joblib\parallel.py", line 1384, in _dispatch
    job = self._backend.apply_async(batch, callback=batch_tracker)
  File "c:\Users\91985\Desktop\123\Projects\ML\Waferfault_detection\env\lib\site-packages\joblib\_parallel_backends.py", line 600, in apply_async
    future = self._workers.submit(func)
  File "c:\Users\91985\Desktop\123\Projects\ML\Waferfault_detection\env\lib\site-packages\joblib\externals\loky\reusable_executor.py", line 225, in submit
    return super().submit(fn, *args, **kwargs)
  File "c:\Users\91985\Desktop\123\Projects\ML\Waferfault_detection\env\lib\site-packages\joblib\externals\loky\process_executor.py", line 1228, in submit
    raise ShutdownExecutorError(
joblib.externals.loky.process_executor.ShutdownExecutorError: cannot schedule new futures after shutdown
[ 2023-12-11 20:21:23,982 ] 28 concurrent.futures - ERROR - exception calling callback for <Future at 0x1db75a6d760 state=finished returned list>
Traceback (most recent call last):
  File "c:\Users\91985\Desktop\123\Projects\ML\Waferfault_detection\env\lib\site-packages\joblib\externals\loky\_base.py", line 26, in _invoke_callbacks
    callback(self)
  File "c:\Users\91985\Desktop\123\Projects\ML\Waferfault_detection\env\lib\site-packages\joblib\parallel.py", line 814, in __call__
    self._dispatch_new()
  File "c:\Users\91985\Desktop\123\Projects\ML\Waferfault_detection\env\lib\site-packages\joblib\parallel.py", line 829, in _dispatch_new
    self.parallel.dispatch_next()
  File "c:\Users\91985\Desktop\123\Projects\ML\Waferfault_detection\env\lib\site-packages\joblib\parallel.py", line 1395, in dispatch_next
    if not self.dispatch_one_batch(self._original_iterator):
  File "c:\Users\91985\Desktop\123\Projects\ML\Waferfault_detection\env\lib\site-packages\joblib\parallel.py", line 1462, in dispatch_one_batch
    self._dispatch(tasks)
  File "c:\Users\91985\Desktop\123\Projects\ML\Waferfault_detection\env\lib\site-packages\joblib\parallel.py", line 1384, in _dispatch
    job = self._backend.apply_async(batch, callback=batch_tracker)
  File "c:\Users\91985\Desktop\123\Projects\ML\Waferfault_detection\env\lib\site-packages\joblib\_parallel_backends.py", line 600, in apply_async
    future = self._workers.submit(func)
  File "c:\Users\91985\Desktop\123\Projects\ML\Waferfault_detection\env\lib\site-packages\joblib\externals\loky\reusable_executor.py", line 225, in submit
    return super().submit(fn, *args, **kwargs)
  File "c:\Users\91985\Desktop\123\Projects\ML\Waferfault_detection\env\lib\site-packages\joblib\externals\loky\process_executor.py", line 1228, in submit
    raise ShutdownExecutorError(
joblib.externals.loky.process_executor.ShutdownExecutorError: cannot schedule new futures after shutdown
[ 2023-12-11 20:21:24,400 ] 28 concurrent.futures - ERROR - exception calling callback for <Future at 0x1db727ce250 state=finished returned list>
Traceback (most recent call last):
  File "c:\Users\91985\Desktop\123\Projects\ML\Waferfault_detection\env\lib\site-packages\joblib\externals\loky\_base.py", line 26, in _invoke_callbacks
    callback(self)
  File "c:\Users\91985\Desktop\123\Projects\ML\Waferfault_detection\env\lib\site-packages\joblib\parallel.py", line 814, in __call__
    self._dispatch_new()
  File "c:\Users\91985\Desktop\123\Projects\ML\Waferfault_detection\env\lib\site-packages\joblib\parallel.py", line 829, in _dispatch_new
    self.parallel.dispatch_next()
  File "c:\Users\91985\Desktop\123\Projects\ML\Waferfault_detection\env\lib\site-packages\joblib\parallel.py", line 1395, in dispatch_next
    if not self.dispatch_one_batch(self._original_iterator):
  File "c:\Users\91985\Desktop\123\Projects\ML\Waferfault_detection\env\lib\site-packages\joblib\parallel.py", line 1462, in dispatch_one_batch
    self._dispatch(tasks)
  File "c:\Users\91985\Desktop\123\Projects\ML\Waferfault_detection\env\lib\site-packages\joblib\parallel.py", line 1384, in _dispatch
    job = self._backend.apply_async(batch, callback=batch_tracker)
  File "c:\Users\91985\Desktop\123\Projects\ML\Waferfault_detection\env\lib\site-packages\joblib\_parallel_backends.py", line 600, in apply_async
    future = self._workers.submit(func)
  File "c:\Users\91985\Desktop\123\Projects\ML\Waferfault_detection\env\lib\site-packages\joblib\externals\loky\reusable_executor.py", line 225, in submit
    return super().submit(fn, *args, **kwargs)
  File "c:\Users\91985\Desktop\123\Projects\ML\Waferfault_detection\env\lib\site-packages\joblib\externals\loky\process_executor.py", line 1228, in submit
    raise ShutdownExecutorError(
joblib.externals.loky.process_executor.ShutdownExecutorError: cannot schedule new futures after shutdown
[ 2023-12-11 20:21:24,690 ] 28 concurrent.futures - ERROR - exception calling callback for <Future at 0x1db72d32bb0 state=finished returned list>
Traceback (most recent call last):
  File "c:\Users\91985\Desktop\123\Projects\ML\Waferfault_detection\env\lib\site-packages\joblib\externals\loky\_base.py", line 26, in _invoke_callbacks
    callback(self)
  File "c:\Users\91985\Desktop\123\Projects\ML\Waferfault_detection\env\lib\site-packages\joblib\parallel.py", line 814, in __call__
    self._dispatch_new()
  File "c:\Users\91985\Desktop\123\Projects\ML\Waferfault_detection\env\lib\site-packages\joblib\parallel.py", line 829, in _dispatch_new
    self.parallel.dispatch_next()
  File "c:\Users\91985\Desktop\123\Projects\ML\Waferfault_detection\env\lib\site-packages\joblib\parallel.py", line 1395, in dispatch_next
    if not self.dispatch_one_batch(self._original_iterator):
  File "c:\Users\91985\Desktop\123\Projects\ML\Waferfault_detection\env\lib\site-packages\joblib\parallel.py", line 1462, in dispatch_one_batch
    self._dispatch(tasks)
  File "c:\Users\91985\Desktop\123\Projects\ML\Waferfault_detection\env\lib\site-packages\joblib\parallel.py", line 1384, in _dispatch
    job = self._backend.apply_async(batch, callback=batch_tracker)
  File "c:\Users\91985\Desktop\123\Projects\ML\Waferfault_detection\env\lib\site-packages\joblib\_parallel_backends.py", line 600, in apply_async
    future = self._workers.submit(func)
  File "c:\Users\91985\Desktop\123\Projects\ML\Waferfault_detection\env\lib\site-packages\joblib\externals\loky\reusable_executor.py", line 225, in submit
    return super().submit(fn, *args, **kwargs)
  File "c:\Users\91985\Desktop\123\Projects\ML\Waferfault_detection\env\lib\site-packages\joblib\externals\loky\process_executor.py", line 1228, in submit
    raise ShutdownExecutorError(
joblib.externals.loky.process_executor.ShutdownExecutorError: cannot schedule new futures after shutdown
[ 2023-12-11 20:21:24,889 ] 28 concurrent.futures - ERROR - exception calling callback for <Future at 0x1db72d32490 state=finished returned list>
Traceback (most recent call last):
  File "c:\Users\91985\Desktop\123\Projects\ML\Waferfault_detection\env\lib\site-packages\joblib\externals\loky\_base.py", line 26, in _invoke_callbacks
    callback(self)
  File "c:\Users\91985\Desktop\123\Projects\ML\Waferfault_detection\env\lib\site-packages\joblib\parallel.py", line 814, in __call__
    self._dispatch_new()
  File "c:\Users\91985\Desktop\123\Projects\ML\Waferfault_detection\env\lib\site-packages\joblib\parallel.py", line 829, in _dispatch_new
    self.parallel.dispatch_next()
  File "c:\Users\91985\Desktop\123\Projects\ML\Waferfault_detection\env\lib\site-packages\joblib\parallel.py", line 1395, in dispatch_next
    if not self.dispatch_one_batch(self._original_iterator):
  File "c:\Users\91985\Desktop\123\Projects\ML\Waferfault_detection\env\lib\site-packages\joblib\parallel.py", line 1462, in dispatch_one_batch
    self._dispatch(tasks)
  File "c:\Users\91985\Desktop\123\Projects\ML\Waferfault_detection\env\lib\site-packages\joblib\parallel.py", line 1384, in _dispatch
    job = self._backend.apply_async(batch, callback=batch_tracker)
  File "c:\Users\91985\Desktop\123\Projects\ML\Waferfault_detection\env\lib\site-packages\joblib\_parallel_backends.py", line 600, in apply_async
    future = self._workers.submit(func)
  File "c:\Users\91985\Desktop\123\Projects\ML\Waferfault_detection\env\lib\site-packages\joblib\externals\loky\reusable_executor.py", line 225, in submit
    return super().submit(fn, *args, **kwargs)
  File "c:\Users\91985\Desktop\123\Projects\ML\Waferfault_detection\env\lib\site-packages\joblib\externals\loky\process_executor.py", line 1228, in submit
    raise ShutdownExecutorError(
joblib.externals.loky.process_executor.ShutdownExecutorError: cannot schedule new futures after shutdown
[ 2023-12-11 20:21:25,161 ] 28 concurrent.futures - ERROR - exception calling callback for <Future at 0x1db748165e0 state=finished returned list>
Traceback (most recent call last):
  File "c:\Users\91985\Desktop\123\Projects\ML\Waferfault_detection\env\lib\site-packages\joblib\externals\loky\_base.py", line 26, in _invoke_callbacks
    callback(self)
  File "c:\Users\91985\Desktop\123\Projects\ML\Waferfault_detection\env\lib\site-packages\joblib\parallel.py", line 814, in __call__
    self._dispatch_new()
  File "c:\Users\91985\Desktop\123\Projects\ML\Waferfault_detection\env\lib\site-packages\joblib\parallel.py", line 829, in _dispatch_new
    self.parallel.dispatch_next()
  File "c:\Users\91985\Desktop\123\Projects\ML\Waferfault_detection\env\lib\site-packages\joblib\parallel.py", line 1395, in dispatch_next
    if not self.dispatch_one_batch(self._original_iterator):
  File "c:\Users\91985\Desktop\123\Projects\ML\Waferfault_detection\env\lib\site-packages\joblib\parallel.py", line 1462, in dispatch_one_batch
    self._dispatch(tasks)
  File "c:\Users\91985\Desktop\123\Projects\ML\Waferfault_detection\env\lib\site-packages\joblib\parallel.py", line 1384, in _dispatch
    job = self._backend.apply_async(batch, callback=batch_tracker)
  File "c:\Users\91985\Desktop\123\Projects\ML\Waferfault_detection\env\lib\site-packages\joblib\_parallel_backends.py", line 600, in apply_async
    future = self._workers.submit(func)
  File "c:\Users\91985\Desktop\123\Projects\ML\Waferfault_detection\env\lib\site-packages\joblib\externals\loky\reusable_executor.py", line 225, in submit
    return super().submit(fn, *args, **kwargs)
  File "c:\Users\91985\Desktop\123\Projects\ML\Waferfault_detection\env\lib\site-packages\joblib\externals\loky\process_executor.py", line 1228, in submit
    raise ShutdownExecutorError(
joblib.externals.loky.process_executor.ShutdownExecutorError: cannot schedule new futures after shutdown
[ 2023-12-11 20:21:25,718 ] 28 concurrent.futures - ERROR - exception calling callback for <Future at 0x1db727cf0d0 state=finished returned list>
Traceback (most recent call last):
  File "c:\Users\91985\Desktop\123\Projects\ML\Waferfault_detection\env\lib\site-packages\joblib\externals\loky\_base.py", line 26, in _invoke_callbacks
    callback(self)
  File "c:\Users\91985\Desktop\123\Projects\ML\Waferfault_detection\env\lib\site-packages\joblib\parallel.py", line 814, in __call__
    self._dispatch_new()
  File "c:\Users\91985\Desktop\123\Projects\ML\Waferfault_detection\env\lib\site-packages\joblib\parallel.py", line 829, in _dispatch_new
    self.parallel.dispatch_next()
  File "c:\Users\91985\Desktop\123\Projects\ML\Waferfault_detection\env\lib\site-packages\joblib\parallel.py", line 1395, in dispatch_next
    if not self.dispatch_one_batch(self._original_iterator):
  File "c:\Users\91985\Desktop\123\Projects\ML\Waferfault_detection\env\lib\site-packages\joblib\parallel.py", line 1462, in dispatch_one_batch
    self._dispatch(tasks)
  File "c:\Users\91985\Desktop\123\Projects\ML\Waferfault_detection\env\lib\site-packages\joblib\parallel.py", line 1384, in _dispatch
    job = self._backend.apply_async(batch, callback=batch_tracker)
  File "c:\Users\91985\Desktop\123\Projects\ML\Waferfault_detection\env\lib\site-packages\joblib\_parallel_backends.py", line 600, in apply_async
    future = self._workers.submit(func)
  File "c:\Users\91985\Desktop\123\Projects\ML\Waferfault_detection\env\lib\site-packages\joblib\externals\loky\reusable_executor.py", line 225, in submit
    return super().submit(fn, *args, **kwargs)
  File "c:\Users\91985\Desktop\123\Projects\ML\Waferfault_detection\env\lib\site-packages\joblib\externals\loky\process_executor.py", line 1228, in submit
    raise ShutdownExecutorError(
joblib.externals.loky.process_executor.ShutdownExecutorError: cannot schedule new futures after shutdown
