[ 2023-12-11 20:13:58,495 ] 96 werkzeug - WARNING -  * Debugger is active!
[ 2023-12-11 20:13:58,502 ] 96 werkzeug - INFO -  * Debugger PIN: 782-199-451
[ 2023-12-11 20:14:24,390 ] 92 root - INFO - Entered initiate_data_ingestion method of Data_Ingestion class
[ 2023-12-11 20:14:24,390 ] 60 root - INFO - Exporting data from mongodb
[ 2023-12-11 20:14:27,308 ] 69 root - INFO - Saving exported data into feature store file path: artifacts
[ 2023-12-11 20:14:27,367 ] 98 root - INFO - Got the data from mongodb
[ 2023-12-11 20:14:27,367 ] 101 root - INFO - Exited initiate_data_ingestion method of Data_Ingestion class
[ 2023-12-11 20:14:27,367 ] 99 root - INFO - Entered initiate_data_transformation method of Data_Transformation class
[ 2023-12-11 20:14:27,492 ] 39 root - INFO - Entered the save_object method of MainUtils class
[ 2023-12-11 20:14:27,492 ] 45 root - INFO - Exited the save_object method of MainUtils class
[ 2023-12-11 20:14:27,494 ] 145 root - INFO - Splitting training and testing input and target feature
[ 2023-12-11 20:14:27,494 ] 156 root - INFO - Extracting model config file path
[ 2023-12-11 20:14:27,494 ] 163 root - INFO - Extracting model config file path
[ 2023-12-11 20:14:37,375 ] 96 werkzeug - INFO -  * Detected change in 'C:\\Users\\91985\\Desktop\\123\\Projects\\ML\\Waferfault_detection\\src\\logger.py', reloading
[ 2023-12-11 20:14:37,497 ] 28 concurrent.futures - ERROR - exception calling callback for <Future at 0x245d9fa5bb0 state=finished returned list>
Traceback (most recent call last):
  File "c:\Users\91985\Desktop\123\Projects\ML\Waferfault_detection\env\lib\site-packages\joblib\externals\loky\_base.py", line 26, in _invoke_callbacks
    callback(self)
  File "c:\Users\91985\Desktop\123\Projects\ML\Waferfault_detection\env\lib\site-packages\joblib\parallel.py", line 814, in __call__
    self._dispatch_new()
  File "c:\Users\91985\Desktop\123\Projects\ML\Waferfault_detection\env\lib\site-packages\joblib\parallel.py", line 829, in _dispatch_new
    self.parallel.dispatch_next()
  File "c:\Users\91985\Desktop\123\Projects\ML\Waferfault_detection\env\lib\site-packages\joblib\parallel.py", line 1395, in dispatch_next
    if not self.dispatch_one_batch(self._original_iterator):
  File "c:\Users\91985\Desktop\123\Projects\ML\Waferfault_detection\env\lib\site-packages\joblib\parallel.py", line 1462, in dispatch_one_batch
    self._dispatch(tasks)
  File "c:\Users\91985\Desktop\123\Projects\ML\Waferfault_detection\env\lib\site-packages\joblib\parallel.py", line 1384, in _dispatch
    job = self._backend.apply_async(batch, callback=batch_tracker)
  File "c:\Users\91985\Desktop\123\Projects\ML\Waferfault_detection\env\lib\site-packages\joblib\_parallel_backends.py", line 600, in apply_async
    future = self._workers.submit(func)
  File "c:\Users\91985\Desktop\123\Projects\ML\Waferfault_detection\env\lib\site-packages\joblib\externals\loky\reusable_executor.py", line 225, in submit
    return super().submit(fn, *args, **kwargs)
  File "c:\Users\91985\Desktop\123\Projects\ML\Waferfault_detection\env\lib\site-packages\joblib\externals\loky\process_executor.py", line 1228, in submit
    raise ShutdownExecutorError(
joblib.externals.loky.process_executor.ShutdownExecutorError: cannot schedule new futures after shutdown
[ 2023-12-11 20:14:37,578 ] 28 concurrent.futures - ERROR - exception calling callback for <Future at 0x245da564ee0 state=finished returned list>
Traceback (most recent call last):
  File "c:\Users\91985\Desktop\123\Projects\ML\Waferfault_detection\env\lib\site-packages\joblib\externals\loky\_base.py", line 26, in _invoke_callbacks
    callback(self)
  File "c:\Users\91985\Desktop\123\Projects\ML\Waferfault_detection\env\lib\site-packages\joblib\parallel.py", line 814, in __call__
    self._dispatch_new()
  File "c:\Users\91985\Desktop\123\Projects\ML\Waferfault_detection\env\lib\site-packages\joblib\parallel.py", line 829, in _dispatch_new
    self.parallel.dispatch_next()
  File "c:\Users\91985\Desktop\123\Projects\ML\Waferfault_detection\env\lib\site-packages\joblib\parallel.py", line 1395, in dispatch_next
    if not self.dispatch_one_batch(self._original_iterator):
  File "c:\Users\91985\Desktop\123\Projects\ML\Waferfault_detection\env\lib\site-packages\joblib\parallel.py", line 1462, in dispatch_one_batch
    self._dispatch(tasks)
  File "c:\Users\91985\Desktop\123\Projects\ML\Waferfault_detection\env\lib\site-packages\joblib\parallel.py", line 1384, in _dispatch
    job = self._backend.apply_async(batch, callback=batch_tracker)
  File "c:\Users\91985\Desktop\123\Projects\ML\Waferfault_detection\env\lib\site-packages\joblib\_parallel_backends.py", line 600, in apply_async
    future = self._workers.submit(func)
  File "c:\Users\91985\Desktop\123\Projects\ML\Waferfault_detection\env\lib\site-packages\joblib\externals\loky\reusable_executor.py", line 225, in submit
    return super().submit(fn, *args, **kwargs)
  File "c:\Users\91985\Desktop\123\Projects\ML\Waferfault_detection\env\lib\site-packages\joblib\externals\loky\process_executor.py", line 1228, in submit
    raise ShutdownExecutorError(
joblib.externals.loky.process_executor.ShutdownExecutorError: cannot schedule new futures after shutdown
[ 2023-12-11 20:14:37,856 ] 28 concurrent.futures - ERROR - exception calling callback for <Future at 0x245da564c70 state=finished returned list>
Traceback (most recent call last):
  File "c:\Users\91985\Desktop\123\Projects\ML\Waferfault_detection\env\lib\site-packages\joblib\externals\loky\_base.py", line 26, in _invoke_callbacks
    callback(self)
  File "c:\Users\91985\Desktop\123\Projects\ML\Waferfault_detection\env\lib\site-packages\joblib\parallel.py", line 814, in __call__
    self._dispatch_new()
  File "c:\Users\91985\Desktop\123\Projects\ML\Waferfault_detection\env\lib\site-packages\joblib\parallel.py", line 829, in _dispatch_new
    self.parallel.dispatch_next()
  File "c:\Users\91985\Desktop\123\Projects\ML\Waferfault_detection\env\lib\site-packages\joblib\parallel.py", line 1395, in dispatch_next
    if not self.dispatch_one_batch(self._original_iterator):
  File "c:\Users\91985\Desktop\123\Projects\ML\Waferfault_detection\env\lib\site-packages\joblib\parallel.py", line 1462, in dispatch_one_batch
    self._dispatch(tasks)
  File "c:\Users\91985\Desktop\123\Projects\ML\Waferfault_detection\env\lib\site-packages\joblib\parallel.py", line 1384, in _dispatch
    job = self._backend.apply_async(batch, callback=batch_tracker)
  File "c:\Users\91985\Desktop\123\Projects\ML\Waferfault_detection\env\lib\site-packages\joblib\_parallel_backends.py", line 600, in apply_async
    future = self._workers.submit(func)
  File "c:\Users\91985\Desktop\123\Projects\ML\Waferfault_detection\env\lib\site-packages\joblib\externals\loky\reusable_executor.py", line 225, in submit
    return super().submit(fn, *args, **kwargs)
  File "c:\Users\91985\Desktop\123\Projects\ML\Waferfault_detection\env\lib\site-packages\joblib\externals\loky\process_executor.py", line 1228, in submit
    raise ShutdownExecutorError(
joblib.externals.loky.process_executor.ShutdownExecutorError: cannot schedule new futures after shutdown
[ 2023-12-11 20:14:37,883 ] 28 concurrent.futures - ERROR - exception calling callback for <Future at 0x245da564e20 state=finished returned list>
Traceback (most recent call last):
  File "c:\Users\91985\Desktop\123\Projects\ML\Waferfault_detection\env\lib\site-packages\joblib\externals\loky\_base.py", line 26, in _invoke_callbacks
    callback(self)
  File "c:\Users\91985\Desktop\123\Projects\ML\Waferfault_detection\env\lib\site-packages\joblib\parallel.py", line 814, in __call__
    self._dispatch_new()
  File "c:\Users\91985\Desktop\123\Projects\ML\Waferfault_detection\env\lib\site-packages\joblib\parallel.py", line 829, in _dispatch_new
    self.parallel.dispatch_next()
  File "c:\Users\91985\Desktop\123\Projects\ML\Waferfault_detection\env\lib\site-packages\joblib\parallel.py", line 1395, in dispatch_next
    if not self.dispatch_one_batch(self._original_iterator):
  File "c:\Users\91985\Desktop\123\Projects\ML\Waferfault_detection\env\lib\site-packages\joblib\parallel.py", line 1462, in dispatch_one_batch
    self._dispatch(tasks)
  File "c:\Users\91985\Desktop\123\Projects\ML\Waferfault_detection\env\lib\site-packages\joblib\parallel.py", line 1384, in _dispatch
    job = self._backend.apply_async(batch, callback=batch_tracker)
  File "c:\Users\91985\Desktop\123\Projects\ML\Waferfault_detection\env\lib\site-packages\joblib\_parallel_backends.py", line 600, in apply_async
    future = self._workers.submit(func)
  File "c:\Users\91985\Desktop\123\Projects\ML\Waferfault_detection\env\lib\site-packages\joblib\externals\loky\reusable_executor.py", line 225, in submit
    return super().submit(fn, *args, **kwargs)
  File "c:\Users\91985\Desktop\123\Projects\ML\Waferfault_detection\env\lib\site-packages\joblib\externals\loky\process_executor.py", line 1228, in submit
    raise ShutdownExecutorError(
joblib.externals.loky.process_executor.ShutdownExecutorError: cannot schedule new futures after shutdown
[ 2023-12-11 20:14:37,975 ] 28 concurrent.futures - ERROR - exception calling callback for <Future at 0x245da564fa0 state=finished returned list>
Traceback (most recent call last):
  File "c:\Users\91985\Desktop\123\Projects\ML\Waferfault_detection\env\lib\site-packages\joblib\externals\loky\_base.py", line 26, in _invoke_callbacks
    callback(self)
  File "c:\Users\91985\Desktop\123\Projects\ML\Waferfault_detection\env\lib\site-packages\joblib\parallel.py", line 814, in __call__
    self._dispatch_new()
  File "c:\Users\91985\Desktop\123\Projects\ML\Waferfault_detection\env\lib\site-packages\joblib\parallel.py", line 829, in _dispatch_new
    self.parallel.dispatch_next()
  File "c:\Users\91985\Desktop\123\Projects\ML\Waferfault_detection\env\lib\site-packages\joblib\parallel.py", line 1395, in dispatch_next
    if not self.dispatch_one_batch(self._original_iterator):
  File "c:\Users\91985\Desktop\123\Projects\ML\Waferfault_detection\env\lib\site-packages\joblib\parallel.py", line 1462, in dispatch_one_batch
    self._dispatch(tasks)
  File "c:\Users\91985\Desktop\123\Projects\ML\Waferfault_detection\env\lib\site-packages\joblib\parallel.py", line 1384, in _dispatch
    job = self._backend.apply_async(batch, callback=batch_tracker)
  File "c:\Users\91985\Desktop\123\Projects\ML\Waferfault_detection\env\lib\site-packages\joblib\_parallel_backends.py", line 600, in apply_async
    future = self._workers.submit(func)
  File "c:\Users\91985\Desktop\123\Projects\ML\Waferfault_detection\env\lib\site-packages\joblib\externals\loky\reusable_executor.py", line 225, in submit
    return super().submit(fn, *args, **kwargs)
  File "c:\Users\91985\Desktop\123\Projects\ML\Waferfault_detection\env\lib\site-packages\joblib\externals\loky\process_executor.py", line 1228, in submit
    raise ShutdownExecutorError(
joblib.externals.loky.process_executor.ShutdownExecutorError: cannot schedule new futures after shutdown
[ 2023-12-11 20:14:38,168 ] 28 concurrent.futures - ERROR - exception calling callback for <Future at 0x245da5710a0 state=finished returned list>
Traceback (most recent call last):
  File "c:\Users\91985\Desktop\123\Projects\ML\Waferfault_detection\env\lib\site-packages\joblib\externals\loky\_base.py", line 26, in _invoke_callbacks
    callback(self)
  File "c:\Users\91985\Desktop\123\Projects\ML\Waferfault_detection\env\lib\site-packages\joblib\parallel.py", line 814, in __call__
    self._dispatch_new()
  File "c:\Users\91985\Desktop\123\Projects\ML\Waferfault_detection\env\lib\site-packages\joblib\parallel.py", line 829, in _dispatch_new
    self.parallel.dispatch_next()
  File "c:\Users\91985\Desktop\123\Projects\ML\Waferfault_detection\env\lib\site-packages\joblib\parallel.py", line 1395, in dispatch_next
    if not self.dispatch_one_batch(self._original_iterator):
  File "c:\Users\91985\Desktop\123\Projects\ML\Waferfault_detection\env\lib\site-packages\joblib\parallel.py", line 1462, in dispatch_one_batch
    self._dispatch(tasks)
  File "c:\Users\91985\Desktop\123\Projects\ML\Waferfault_detection\env\lib\site-packages\joblib\parallel.py", line 1384, in _dispatch
    job = self._backend.apply_async(batch, callback=batch_tracker)
  File "c:\Users\91985\Desktop\123\Projects\ML\Waferfault_detection\env\lib\site-packages\joblib\_parallel_backends.py", line 600, in apply_async
    future = self._workers.submit(func)
  File "c:\Users\91985\Desktop\123\Projects\ML\Waferfault_detection\env\lib\site-packages\joblib\externals\loky\reusable_executor.py", line 225, in submit
    return super().submit(fn, *args, **kwargs)
  File "c:\Users\91985\Desktop\123\Projects\ML\Waferfault_detection\env\lib\site-packages\joblib\externals\loky\process_executor.py", line 1228, in submit
    raise ShutdownExecutorError(
joblib.externals.loky.process_executor.ShutdownExecutorError: cannot schedule new futures after shutdown
[ 2023-12-11 20:14:38,267 ] 28 concurrent.futures - ERROR - exception calling callback for <Future at 0x245da571160 state=finished returned list>
Traceback (most recent call last):
  File "c:\Users\91985\Desktop\123\Projects\ML\Waferfault_detection\env\lib\site-packages\joblib\externals\loky\_base.py", line 26, in _invoke_callbacks
    callback(self)
  File "c:\Users\91985\Desktop\123\Projects\ML\Waferfault_detection\env\lib\site-packages\joblib\parallel.py", line 814, in __call__
    self._dispatch_new()
  File "c:\Users\91985\Desktop\123\Projects\ML\Waferfault_detection\env\lib\site-packages\joblib\parallel.py", line 829, in _dispatch_new
    self.parallel.dispatch_next()
  File "c:\Users\91985\Desktop\123\Projects\ML\Waferfault_detection\env\lib\site-packages\joblib\parallel.py", line 1395, in dispatch_next
    if not self.dispatch_one_batch(self._original_iterator):
  File "c:\Users\91985\Desktop\123\Projects\ML\Waferfault_detection\env\lib\site-packages\joblib\parallel.py", line 1462, in dispatch_one_batch
    self._dispatch(tasks)
  File "c:\Users\91985\Desktop\123\Projects\ML\Waferfault_detection\env\lib\site-packages\joblib\parallel.py", line 1384, in _dispatch
    job = self._backend.apply_async(batch, callback=batch_tracker)
  File "c:\Users\91985\Desktop\123\Projects\ML\Waferfault_detection\env\lib\site-packages\joblib\_parallel_backends.py", line 600, in apply_async
    future = self._workers.submit(func)
  File "c:\Users\91985\Desktop\123\Projects\ML\Waferfault_detection\env\lib\site-packages\joblib\externals\loky\reusable_executor.py", line 225, in submit
    return super().submit(fn, *args, **kwargs)
  File "c:\Users\91985\Desktop\123\Projects\ML\Waferfault_detection\env\lib\site-packages\joblib\externals\loky\process_executor.py", line 1228, in submit
    raise ShutdownExecutorError(
joblib.externals.loky.process_executor.ShutdownExecutorError: cannot schedule new futures after shutdown
[ 2023-12-11 20:14:38,267 ] 28 concurrent.futures - ERROR - exception calling callback for <Future at 0x245da564d60 state=finished returned list>
Traceback (most recent call last):
  File "c:\Users\91985\Desktop\123\Projects\ML\Waferfault_detection\env\lib\site-packages\joblib\externals\loky\_base.py", line 26, in _invoke_callbacks
    callback(self)
  File "c:\Users\91985\Desktop\123\Projects\ML\Waferfault_detection\env\lib\site-packages\joblib\parallel.py", line 814, in __call__
    self._dispatch_new()
  File "c:\Users\91985\Desktop\123\Projects\ML\Waferfault_detection\env\lib\site-packages\joblib\parallel.py", line 829, in _dispatch_new
    self.parallel.dispatch_next()
  File "c:\Users\91985\Desktop\123\Projects\ML\Waferfault_detection\env\lib\site-packages\joblib\parallel.py", line 1395, in dispatch_next
    if not self.dispatch_one_batch(self._original_iterator):
  File "c:\Users\91985\Desktop\123\Projects\ML\Waferfault_detection\env\lib\site-packages\joblib\parallel.py", line 1462, in dispatch_one_batch
    self._dispatch(tasks)
  File "c:\Users\91985\Desktop\123\Projects\ML\Waferfault_detection\env\lib\site-packages\joblib\parallel.py", line 1384, in _dispatch
    job = self._backend.apply_async(batch, callback=batch_tracker)
  File "c:\Users\91985\Desktop\123\Projects\ML\Waferfault_detection\env\lib\site-packages\joblib\_parallel_backends.py", line 600, in apply_async
    future = self._workers.submit(func)
  File "c:\Users\91985\Desktop\123\Projects\ML\Waferfault_detection\env\lib\site-packages\joblib\externals\loky\reusable_executor.py", line 225, in submit
    return super().submit(fn, *args, **kwargs)
  File "c:\Users\91985\Desktop\123\Projects\ML\Waferfault_detection\env\lib\site-packages\joblib\externals\loky\process_executor.py", line 1228, in submit
    raise ShutdownExecutorError(
joblib.externals.loky.process_executor.ShutdownExecutorError: cannot schedule new futures after shutdown
[ 2023-12-11 20:14:38,602 ] 28 concurrent.futures - ERROR - exception calling callback for <Future at 0x245da5719a0 state=finished returned list>
Traceback (most recent call last):
  File "c:\Users\91985\Desktop\123\Projects\ML\Waferfault_detection\env\lib\site-packages\joblib\externals\loky\_base.py", line 26, in _invoke_callbacks
    callback(self)
  File "c:\Users\91985\Desktop\123\Projects\ML\Waferfault_detection\env\lib\site-packages\joblib\parallel.py", line 814, in __call__
    self._dispatch_new()
  File "c:\Users\91985\Desktop\123\Projects\ML\Waferfault_detection\env\lib\site-packages\joblib\parallel.py", line 829, in _dispatch_new
    self.parallel.dispatch_next()
  File "c:\Users\91985\Desktop\123\Projects\ML\Waferfault_detection\env\lib\site-packages\joblib\parallel.py", line 1395, in dispatch_next
    if not self.dispatch_one_batch(self._original_iterator):
  File "c:\Users\91985\Desktop\123\Projects\ML\Waferfault_detection\env\lib\site-packages\joblib\parallel.py", line 1462, in dispatch_one_batch
    self._dispatch(tasks)
  File "c:\Users\91985\Desktop\123\Projects\ML\Waferfault_detection\env\lib\site-packages\joblib\parallel.py", line 1384, in _dispatch
    job = self._backend.apply_async(batch, callback=batch_tracker)
  File "c:\Users\91985\Desktop\123\Projects\ML\Waferfault_detection\env\lib\site-packages\joblib\_parallel_backends.py", line 600, in apply_async
    future = self._workers.submit(func)
  File "c:\Users\91985\Desktop\123\Projects\ML\Waferfault_detection\env\lib\site-packages\joblib\externals\loky\reusable_executor.py", line 225, in submit
    return super().submit(fn, *args, **kwargs)
  File "c:\Users\91985\Desktop\123\Projects\ML\Waferfault_detection\env\lib\site-packages\joblib\externals\loky\process_executor.py", line 1228, in submit
    raise ShutdownExecutorError(
joblib.externals.loky.process_executor.ShutdownExecutorError: cannot schedule new futures after shutdown
[ 2023-12-11 20:14:38,652 ] 28 concurrent.futures - ERROR - exception calling callback for <Future at 0x245da571a60 state=finished returned list>
Traceback (most recent call last):
  File "c:\Users\91985\Desktop\123\Projects\ML\Waferfault_detection\env\lib\site-packages\joblib\externals\loky\_base.py", line 26, in _invoke_callbacks
    callback(self)
  File "c:\Users\91985\Desktop\123\Projects\ML\Waferfault_detection\env\lib\site-packages\joblib\parallel.py", line 814, in __call__
    self._dispatch_new()
  File "c:\Users\91985\Desktop\123\Projects\ML\Waferfault_detection\env\lib\site-packages\joblib\parallel.py", line 829, in _dispatch_new
    self.parallel.dispatch_next()
  File "c:\Users\91985\Desktop\123\Projects\ML\Waferfault_detection\env\lib\site-packages\joblib\parallel.py", line 1395, in dispatch_next
    if not self.dispatch_one_batch(self._original_iterator):
  File "c:\Users\91985\Desktop\123\Projects\ML\Waferfault_detection\env\lib\site-packages\joblib\parallel.py", line 1462, in dispatch_one_batch
    self._dispatch(tasks)
  File "c:\Users\91985\Desktop\123\Projects\ML\Waferfault_detection\env\lib\site-packages\joblib\parallel.py", line 1384, in _dispatch
    job = self._backend.apply_async(batch, callback=batch_tracker)
  File "c:\Users\91985\Desktop\123\Projects\ML\Waferfault_detection\env\lib\site-packages\joblib\_parallel_backends.py", line 600, in apply_async
    future = self._workers.submit(func)
  File "c:\Users\91985\Desktop\123\Projects\ML\Waferfault_detection\env\lib\site-packages\joblib\externals\loky\reusable_executor.py", line 225, in submit
    return super().submit(fn, *args, **kwargs)
  File "c:\Users\91985\Desktop\123\Projects\ML\Waferfault_detection\env\lib\site-packages\joblib\externals\loky\process_executor.py", line 1228, in submit
    raise ShutdownExecutorError(
joblib.externals.loky.process_executor.ShutdownExecutorError: cannot schedule new futures after shutdown
[ 2023-12-11 20:14:38,830 ] 28 concurrent.futures - ERROR - exception calling callback for <Future at 0x245da56c550 state=finished returned list>
Traceback (most recent call last):
  File "c:\Users\91985\Desktop\123\Projects\ML\Waferfault_detection\env\lib\site-packages\joblib\externals\loky\_base.py", line 26, in _invoke_callbacks
    callback(self)
  File "c:\Users\91985\Desktop\123\Projects\ML\Waferfault_detection\env\lib\site-packages\joblib\parallel.py", line 814, in __call__
    self._dispatch_new()
  File "c:\Users\91985\Desktop\123\Projects\ML\Waferfault_detection\env\lib\site-packages\joblib\parallel.py", line 829, in _dispatch_new
    self.parallel.dispatch_next()
  File "c:\Users\91985\Desktop\123\Projects\ML\Waferfault_detection\env\lib\site-packages\joblib\parallel.py", line 1395, in dispatch_next
    if not self.dispatch_one_batch(self._original_iterator):
  File "c:\Users\91985\Desktop\123\Projects\ML\Waferfault_detection\env\lib\site-packages\joblib\parallel.py", line 1462, in dispatch_one_batch
    self._dispatch(tasks)
  File "c:\Users\91985\Desktop\123\Projects\ML\Waferfault_detection\env\lib\site-packages\joblib\parallel.py", line 1384, in _dispatch
    job = self._backend.apply_async(batch, callback=batch_tracker)
  File "c:\Users\91985\Desktop\123\Projects\ML\Waferfault_detection\env\lib\site-packages\joblib\_parallel_backends.py", line 600, in apply_async
    future = self._workers.submit(func)
  File "c:\Users\91985\Desktop\123\Projects\ML\Waferfault_detection\env\lib\site-packages\joblib\externals\loky\reusable_executor.py", line 225, in submit
    return super().submit(fn, *args, **kwargs)
  File "c:\Users\91985\Desktop\123\Projects\ML\Waferfault_detection\env\lib\site-packages\joblib\externals\loky\process_executor.py", line 1228, in submit
    raise ShutdownExecutorError(
joblib.externals.loky.process_executor.ShutdownExecutorError: cannot schedule new futures after shutdown
[ 2023-12-11 20:14:39,026 ] 28 concurrent.futures - ERROR - exception calling callback for <Future at 0x245da571b20 state=finished returned list>
Traceback (most recent call last):
  File "c:\Users\91985\Desktop\123\Projects\ML\Waferfault_detection\env\lib\site-packages\joblib\externals\loky\_base.py", line 26, in _invoke_callbacks
    callback(self)
  File "c:\Users\91985\Desktop\123\Projects\ML\Waferfault_detection\env\lib\site-packages\joblib\parallel.py", line 814, in __call__
    self._dispatch_new()
  File "c:\Users\91985\Desktop\123\Projects\ML\Waferfault_detection\env\lib\site-packages\joblib\parallel.py", line 829, in _dispatch_new
    self.parallel.dispatch_next()
  File "c:\Users\91985\Desktop\123\Projects\ML\Waferfault_detection\env\lib\site-packages\joblib\parallel.py", line 1395, in dispatch_next
    if not self.dispatch_one_batch(self._original_iterator):
  File "c:\Users\91985\Desktop\123\Projects\ML\Waferfault_detection\env\lib\site-packages\joblib\parallel.py", line 1462, in dispatch_one_batch
    self._dispatch(tasks)
  File "c:\Users\91985\Desktop\123\Projects\ML\Waferfault_detection\env\lib\site-packages\joblib\parallel.py", line 1384, in _dispatch
    job = self._backend.apply_async(batch, callback=batch_tracker)
  File "c:\Users\91985\Desktop\123\Projects\ML\Waferfault_detection\env\lib\site-packages\joblib\_parallel_backends.py", line 600, in apply_async
    future = self._workers.submit(func)
  File "c:\Users\91985\Desktop\123\Projects\ML\Waferfault_detection\env\lib\site-packages\joblib\externals\loky\reusable_executor.py", line 225, in submit
    return super().submit(fn, *args, **kwargs)
  File "c:\Users\91985\Desktop\123\Projects\ML\Waferfault_detection\env\lib\site-packages\joblib\externals\loky\process_executor.py", line 1228, in submit
    raise ShutdownExecutorError(
joblib.externals.loky.process_executor.ShutdownExecutorError: cannot schedule new futures after shutdown
[ 2023-12-11 20:14:39,063 ] 28 concurrent.futures - ERROR - exception calling callback for <Future at 0x245da56c310 state=finished returned list>
Traceback (most recent call last):
  File "c:\Users\91985\Desktop\123\Projects\ML\Waferfault_detection\env\lib\site-packages\joblib\externals\loky\_base.py", line 26, in _invoke_callbacks
    callback(self)
  File "c:\Users\91985\Desktop\123\Projects\ML\Waferfault_detection\env\lib\site-packages\joblib\parallel.py", line 814, in __call__
    self._dispatch_new()
  File "c:\Users\91985\Desktop\123\Projects\ML\Waferfault_detection\env\lib\site-packages\joblib\parallel.py", line 829, in _dispatch_new
    self.parallel.dispatch_next()
  File "c:\Users\91985\Desktop\123\Projects\ML\Waferfault_detection\env\lib\site-packages\joblib\parallel.py", line 1395, in dispatch_next
    if not self.dispatch_one_batch(self._original_iterator):
  File "c:\Users\91985\Desktop\123\Projects\ML\Waferfault_detection\env\lib\site-packages\joblib\parallel.py", line 1462, in dispatch_one_batch
    self._dispatch(tasks)
  File "c:\Users\91985\Desktop\123\Projects\ML\Waferfault_detection\env\lib\site-packages\joblib\parallel.py", line 1384, in _dispatch
    job = self._backend.apply_async(batch, callback=batch_tracker)
  File "c:\Users\91985\Desktop\123\Projects\ML\Waferfault_detection\env\lib\site-packages\joblib\_parallel_backends.py", line 600, in apply_async
    future = self._workers.submit(func)
  File "c:\Users\91985\Desktop\123\Projects\ML\Waferfault_detection\env\lib\site-packages\joblib\externals\loky\reusable_executor.py", line 225, in submit
    return super().submit(fn, *args, **kwargs)
  File "c:\Users\91985\Desktop\123\Projects\ML\Waferfault_detection\env\lib\site-packages\joblib\externals\loky\process_executor.py", line 1228, in submit
    raise ShutdownExecutorError(
joblib.externals.loky.process_executor.ShutdownExecutorError: cannot schedule new futures after shutdown
[ 2023-12-11 20:14:39,108 ] 28 concurrent.futures - ERROR - exception calling callback for <Future at 0x245da56c250 state=finished returned list>
Traceback (most recent call last):
  File "c:\Users\91985\Desktop\123\Projects\ML\Waferfault_detection\env\lib\site-packages\joblib\externals\loky\_base.py", line 26, in _invoke_callbacks
    callback(self)
  File "c:\Users\91985\Desktop\123\Projects\ML\Waferfault_detection\env\lib\site-packages\joblib\parallel.py", line 814, in __call__
    self._dispatch_new()
  File "c:\Users\91985\Desktop\123\Projects\ML\Waferfault_detection\env\lib\site-packages\joblib\parallel.py", line 829, in _dispatch_new
    self.parallel.dispatch_next()
  File "c:\Users\91985\Desktop\123\Projects\ML\Waferfault_detection\env\lib\site-packages\joblib\parallel.py", line 1395, in dispatch_next
    if not self.dispatch_one_batch(self._original_iterator):
  File "c:\Users\91985\Desktop\123\Projects\ML\Waferfault_detection\env\lib\site-packages\joblib\parallel.py", line 1462, in dispatch_one_batch
    self._dispatch(tasks)
  File "c:\Users\91985\Desktop\123\Projects\ML\Waferfault_detection\env\lib\site-packages\joblib\parallel.py", line 1384, in _dispatch
    job = self._backend.apply_async(batch, callback=batch_tracker)
  File "c:\Users\91985\Desktop\123\Projects\ML\Waferfault_detection\env\lib\site-packages\joblib\_parallel_backends.py", line 600, in apply_async
    future = self._workers.submit(func)
  File "c:\Users\91985\Desktop\123\Projects\ML\Waferfault_detection\env\lib\site-packages\joblib\externals\loky\reusable_executor.py", line 225, in submit
    return super().submit(fn, *args, **kwargs)
  File "c:\Users\91985\Desktop\123\Projects\ML\Waferfault_detection\env\lib\site-packages\joblib\externals\loky\process_executor.py", line 1228, in submit
    raise ShutdownExecutorError(
joblib.externals.loky.process_executor.ShutdownExecutorError: cannot schedule new futures after shutdown
[ 2023-12-11 20:14:39,155 ] 28 concurrent.futures - ERROR - exception calling callback for <Future at 0x245da56c3d0 state=finished returned list>
Traceback (most recent call last):
  File "c:\Users\91985\Desktop\123\Projects\ML\Waferfault_detection\env\lib\site-packages\joblib\externals\loky\_base.py", line 26, in _invoke_callbacks
    callback(self)
  File "c:\Users\91985\Desktop\123\Projects\ML\Waferfault_detection\env\lib\site-packages\joblib\parallel.py", line 814, in __call__
    self._dispatch_new()
  File "c:\Users\91985\Desktop\123\Projects\ML\Waferfault_detection\env\lib\site-packages\joblib\parallel.py", line 829, in _dispatch_new
    self.parallel.dispatch_next()
  File "c:\Users\91985\Desktop\123\Projects\ML\Waferfault_detection\env\lib\site-packages\joblib\parallel.py", line 1395, in dispatch_next
    if not self.dispatch_one_batch(self._original_iterator):
  File "c:\Users\91985\Desktop\123\Projects\ML\Waferfault_detection\env\lib\site-packages\joblib\parallel.py", line 1462, in dispatch_one_batch
    self._dispatch(tasks)
  File "c:\Users\91985\Desktop\123\Projects\ML\Waferfault_detection\env\lib\site-packages\joblib\parallel.py", line 1384, in _dispatch
    job = self._backend.apply_async(batch, callback=batch_tracker)
  File "c:\Users\91985\Desktop\123\Projects\ML\Waferfault_detection\env\lib\site-packages\joblib\_parallel_backends.py", line 600, in apply_async
    future = self._workers.submit(func)
  File "c:\Users\91985\Desktop\123\Projects\ML\Waferfault_detection\env\lib\site-packages\joblib\externals\loky\reusable_executor.py", line 225, in submit
    return super().submit(fn, *args, **kwargs)
  File "c:\Users\91985\Desktop\123\Projects\ML\Waferfault_detection\env\lib\site-packages\joblib\externals\loky\process_executor.py", line 1228, in submit
    raise ShutdownExecutorError(
joblib.externals.loky.process_executor.ShutdownExecutorError: cannot schedule new futures after shutdown
[ 2023-12-11 20:14:39,190 ] 28 concurrent.futures - ERROR - exception calling callback for <Future at 0x245da56c490 state=finished returned list>
Traceback (most recent call last):
  File "c:\Users\91985\Desktop\123\Projects\ML\Waferfault_detection\env\lib\site-packages\joblib\externals\loky\_base.py", line 26, in _invoke_callbacks
    callback(self)
  File "c:\Users\91985\Desktop\123\Projects\ML\Waferfault_detection\env\lib\site-packages\joblib\parallel.py", line 814, in __call__
    self._dispatch_new()
  File "c:\Users\91985\Desktop\123\Projects\ML\Waferfault_detection\env\lib\site-packages\joblib\parallel.py", line 829, in _dispatch_new
    self.parallel.dispatch_next()
  File "c:\Users\91985\Desktop\123\Projects\ML\Waferfault_detection\env\lib\site-packages\joblib\parallel.py", line 1395, in dispatch_next
    if not self.dispatch_one_batch(self._original_iterator):
  File "c:\Users\91985\Desktop\123\Projects\ML\Waferfault_detection\env\lib\site-packages\joblib\parallel.py", line 1462, in dispatch_one_batch
    self._dispatch(tasks)
  File "c:\Users\91985\Desktop\123\Projects\ML\Waferfault_detection\env\lib\site-packages\joblib\parallel.py", line 1384, in _dispatch
    job = self._backend.apply_async(batch, callback=batch_tracker)
  File "c:\Users\91985\Desktop\123\Projects\ML\Waferfault_detection\env\lib\site-packages\joblib\_parallel_backends.py", line 600, in apply_async
    future = self._workers.submit(func)
  File "c:\Users\91985\Desktop\123\Projects\ML\Waferfault_detection\env\lib\site-packages\joblib\externals\loky\reusable_executor.py", line 225, in submit
    return super().submit(fn, *args, **kwargs)
  File "c:\Users\91985\Desktop\123\Projects\ML\Waferfault_detection\env\lib\site-packages\joblib\externals\loky\process_executor.py", line 1228, in submit
    raise ShutdownExecutorError(
joblib.externals.loky.process_executor.ShutdownExecutorError: cannot schedule new futures after shutdown
