[ 2023-12-11 20:12:34,643 ] 96 werkzeug - WARNING -  * Debugger is active!
[ 2023-12-11 20:12:34,649 ] 96 werkzeug - INFO -  * Debugger PIN: 782-199-451
[ 2023-12-11 20:12:39,606 ] 92 root - INFO - Entered initiate_data_ingestion method of Data_Ingestion class
[ 2023-12-11 20:12:39,606 ] 60 root - INFO - Exporting data from mongodb
[ 2023-12-11 20:12:43,195 ] 69 root - INFO - Saving exported data into feature store file path: artifacts
[ 2023-12-11 20:12:43,258 ] 98 root - INFO - Got the data from mongodb
[ 2023-12-11 20:12:43,261 ] 101 root - INFO - Exited initiate_data_ingestion method of Data_Ingestion class
[ 2023-12-11 20:12:43,261 ] 99 root - INFO - Entered initiate_data_transformation method of Data_Transformation class
[ 2023-12-11 20:12:43,494 ] 39 root - INFO - Entered the save_object method of MainUtils class
[ 2023-12-11 20:12:43,494 ] 45 root - INFO - Exited the save_object method of MainUtils class
[ 2023-12-11 20:12:43,494 ] 145 root - INFO - Splitting training and testing input and target feature
[ 2023-12-11 20:12:43,494 ] 156 root - INFO - Extracting model config file path
[ 2023-12-11 20:12:43,494 ] 163 root - INFO - Extracting model config file path
[ 2023-12-11 20:13:05,809 ] 96 werkzeug - INFO -  * Detected change in 'C:\\Users\\91985\\Desktop\\123\\Projects\\ML\\Waferfault_detection\\src\\components\\model_trainer.py', reloading
[ 2023-12-11 20:13:06,248 ] 28 concurrent.futures - ERROR - exception calling callback for <Future at 0x2037ed40640 state=finished returned list>
Traceback (most recent call last):
  File "c:\Users\91985\Desktop\123\Projects\ML\Waferfault_detection\env\lib\site-packages\joblib\externals\loky\_base.py", line 26, in _invoke_callbacks
    callback(self)
  File "c:\Users\91985\Desktop\123\Projects\ML\Waferfault_detection\env\lib\site-packages\joblib\parallel.py", line 814, in __call__
    self._dispatch_new()
  File "c:\Users\91985\Desktop\123\Projects\ML\Waferfault_detection\env\lib\site-packages\joblib\parallel.py", line 829, in _dispatch_new
    self.parallel.dispatch_next()
  File "c:\Users\91985\Desktop\123\Projects\ML\Waferfault_detection\env\lib\site-packages\joblib\parallel.py", line 1395, in dispatch_next
    if not self.dispatch_one_batch(self._original_iterator):
  File "c:\Users\91985\Desktop\123\Projects\ML\Waferfault_detection\env\lib\site-packages\joblib\parallel.py", line 1462, in dispatch_one_batch
    self._dispatch(tasks)
  File "c:\Users\91985\Desktop\123\Projects\ML\Waferfault_detection\env\lib\site-packages\joblib\parallel.py", line 1384, in _dispatch
    job = self._backend.apply_async(batch, callback=batch_tracker)
  File "c:\Users\91985\Desktop\123\Projects\ML\Waferfault_detection\env\lib\site-packages\joblib\_parallel_backends.py", line 600, in apply_async
    future = self._workers.submit(func)
  File "c:\Users\91985\Desktop\123\Projects\ML\Waferfault_detection\env\lib\site-packages\joblib\externals\loky\reusable_executor.py", line 225, in submit
    return super().submit(fn, *args, **kwargs)
  File "c:\Users\91985\Desktop\123\Projects\ML\Waferfault_detection\env\lib\site-packages\joblib\externals\loky\process_executor.py", line 1228, in submit
    raise ShutdownExecutorError(
joblib.externals.loky.process_executor.ShutdownExecutorError: cannot schedule new futures after shutdown
[ 2023-12-11 20:13:06,580 ] 28 concurrent.futures - ERROR - exception calling callback for <Future at 0x20300bd8910 state=finished returned list>
Traceback (most recent call last):
  File "c:\Users\91985\Desktop\123\Projects\ML\Waferfault_detection\env\lib\site-packages\joblib\externals\loky\_base.py", line 26, in _invoke_callbacks
    callback(self)
  File "c:\Users\91985\Desktop\123\Projects\ML\Waferfault_detection\env\lib\site-packages\joblib\parallel.py", line 814, in __call__
    self._dispatch_new()
  File "c:\Users\91985\Desktop\123\Projects\ML\Waferfault_detection\env\lib\site-packages\joblib\parallel.py", line 829, in _dispatch_new
    self.parallel.dispatch_next()
  File "c:\Users\91985\Desktop\123\Projects\ML\Waferfault_detection\env\lib\site-packages\joblib\parallel.py", line 1395, in dispatch_next
    if not self.dispatch_one_batch(self._original_iterator):
  File "c:\Users\91985\Desktop\123\Projects\ML\Waferfault_detection\env\lib\site-packages\joblib\parallel.py", line 1462, in dispatch_one_batch
    self._dispatch(tasks)
  File "c:\Users\91985\Desktop\123\Projects\ML\Waferfault_detection\env\lib\site-packages\joblib\parallel.py", line 1384, in _dispatch
    job = self._backend.apply_async(batch, callback=batch_tracker)
  File "c:\Users\91985\Desktop\123\Projects\ML\Waferfault_detection\env\lib\site-packages\joblib\_parallel_backends.py", line 600, in apply_async
    future = self._workers.submit(func)
  File "c:\Users\91985\Desktop\123\Projects\ML\Waferfault_detection\env\lib\site-packages\joblib\externals\loky\reusable_executor.py", line 225, in submit
    return super().submit(fn, *args, **kwargs)
  File "c:\Users\91985\Desktop\123\Projects\ML\Waferfault_detection\env\lib\site-packages\joblib\externals\loky\process_executor.py", line 1228, in submit
    raise ShutdownExecutorError(
joblib.externals.loky.process_executor.ShutdownExecutorError: cannot schedule new futures after shutdown
[ 2023-12-11 20:13:06,582 ] 28 concurrent.futures - ERROR - exception calling callback for <Future at 0x2037ed4c2b0 state=finished returned list>
Traceback (most recent call last):
  File "c:\Users\91985\Desktop\123\Projects\ML\Waferfault_detection\env\lib\site-packages\joblib\externals\loky\_base.py", line 26, in _invoke_callbacks
    callback(self)
  File "c:\Users\91985\Desktop\123\Projects\ML\Waferfault_detection\env\lib\site-packages\joblib\parallel.py", line 814, in __call__
    self._dispatch_new()
  File "c:\Users\91985\Desktop\123\Projects\ML\Waferfault_detection\env\lib\site-packages\joblib\parallel.py", line 829, in _dispatch_new
    self.parallel.dispatch_next()
  File "c:\Users\91985\Desktop\123\Projects\ML\Waferfault_detection\env\lib\site-packages\joblib\parallel.py", line 1395, in dispatch_next
    if not self.dispatch_one_batch(self._original_iterator):
  File "c:\Users\91985\Desktop\123\Projects\ML\Waferfault_detection\env\lib\site-packages\joblib\parallel.py", line 1462, in dispatch_one_batch
    self._dispatch(tasks)
  File "c:\Users\91985\Desktop\123\Projects\ML\Waferfault_detection\env\lib\site-packages\joblib\parallel.py", line 1384, in _dispatch
    job = self._backend.apply_async(batch, callback=batch_tracker)
  File "c:\Users\91985\Desktop\123\Projects\ML\Waferfault_detection\env\lib\site-packages\joblib\_parallel_backends.py", line 600, in apply_async
    future = self._workers.submit(func)
  File "c:\Users\91985\Desktop\123\Projects\ML\Waferfault_detection\env\lib\site-packages\joblib\externals\loky\reusable_executor.py", line 225, in submit
    return super().submit(fn, *args, **kwargs)
  File "c:\Users\91985\Desktop\123\Projects\ML\Waferfault_detection\env\lib\site-packages\joblib\externals\loky\process_executor.py", line 1228, in submit
    raise ShutdownExecutorError(
joblib.externals.loky.process_executor.ShutdownExecutorError: cannot schedule new futures after shutdown
[ 2023-12-11 20:13:06,584 ] 28 concurrent.futures - ERROR - exception calling callback for <Future at 0x2037ed4cd60 state=finished returned list>
Traceback (most recent call last):
  File "c:\Users\91985\Desktop\123\Projects\ML\Waferfault_detection\env\lib\site-packages\joblib\externals\loky\_base.py", line 26, in _invoke_callbacks
    callback(self)
  File "c:\Users\91985\Desktop\123\Projects\ML\Waferfault_detection\env\lib\site-packages\joblib\parallel.py", line 814, in __call__
    self._dispatch_new()
  File "c:\Users\91985\Desktop\123\Projects\ML\Waferfault_detection\env\lib\site-packages\joblib\parallel.py", line 829, in _dispatch_new
    self.parallel.dispatch_next()
  File "c:\Users\91985\Desktop\123\Projects\ML\Waferfault_detection\env\lib\site-packages\joblib\parallel.py", line 1395, in dispatch_next
    if not self.dispatch_one_batch(self._original_iterator):
  File "c:\Users\91985\Desktop\123\Projects\ML\Waferfault_detection\env\lib\site-packages\joblib\parallel.py", line 1462, in dispatch_one_batch
    self._dispatch(tasks)
  File "c:\Users\91985\Desktop\123\Projects\ML\Waferfault_detection\env\lib\site-packages\joblib\parallel.py", line 1384, in _dispatch
    job = self._backend.apply_async(batch, callback=batch_tracker)
  File "c:\Users\91985\Desktop\123\Projects\ML\Waferfault_detection\env\lib\site-packages\joblib\_parallel_backends.py", line 600, in apply_async
    future = self._workers.submit(func)
  File "c:\Users\91985\Desktop\123\Projects\ML\Waferfault_detection\env\lib\site-packages\joblib\externals\loky\reusable_executor.py", line 225, in submit
    return super().submit(fn, *args, **kwargs)
  File "c:\Users\91985\Desktop\123\Projects\ML\Waferfault_detection\env\lib\site-packages\joblib\externals\loky\process_executor.py", line 1228, in submit
    raise ShutdownExecutorError(
joblib.externals.loky.process_executor.ShutdownExecutorError: cannot schedule new futures after shutdown
[ 2023-12-11 20:13:06,860 ] 28 concurrent.futures - ERROR - exception calling callback for <Future at 0x2037ed4c1c0 state=finished returned list>
Traceback (most recent call last):
  File "c:\Users\91985\Desktop\123\Projects\ML\Waferfault_detection\env\lib\site-packages\joblib\externals\loky\_base.py", line 26, in _invoke_callbacks
    callback(self)
  File "c:\Users\91985\Desktop\123\Projects\ML\Waferfault_detection\env\lib\site-packages\joblib\parallel.py", line 814, in __call__
    self._dispatch_new()
  File "c:\Users\91985\Desktop\123\Projects\ML\Waferfault_detection\env\lib\site-packages\joblib\parallel.py", line 829, in _dispatch_new
    self.parallel.dispatch_next()
  File "c:\Users\91985\Desktop\123\Projects\ML\Waferfault_detection\env\lib\site-packages\joblib\parallel.py", line 1395, in dispatch_next
    if not self.dispatch_one_batch(self._original_iterator):
  File "c:\Users\91985\Desktop\123\Projects\ML\Waferfault_detection\env\lib\site-packages\joblib\parallel.py", line 1462, in dispatch_one_batch
    self._dispatch(tasks)
  File "c:\Users\91985\Desktop\123\Projects\ML\Waferfault_detection\env\lib\site-packages\joblib\parallel.py", line 1384, in _dispatch
    job = self._backend.apply_async(batch, callback=batch_tracker)
  File "c:\Users\91985\Desktop\123\Projects\ML\Waferfault_detection\env\lib\site-packages\joblib\_parallel_backends.py", line 600, in apply_async
    future = self._workers.submit(func)
  File "c:\Users\91985\Desktop\123\Projects\ML\Waferfault_detection\env\lib\site-packages\joblib\externals\loky\reusable_executor.py", line 225, in submit
    return super().submit(fn, *args, **kwargs)
  File "c:\Users\91985\Desktop\123\Projects\ML\Waferfault_detection\env\lib\site-packages\joblib\externals\loky\process_executor.py", line 1228, in submit
    raise ShutdownExecutorError(
joblib.externals.loky.process_executor.ShutdownExecutorError: cannot schedule new futures after shutdown
[ 2023-12-11 20:13:07,211 ] 28 concurrent.futures - ERROR - exception calling callback for <Future at 0x2037ed40670 state=finished returned list>
Traceback (most recent call last):
  File "c:\Users\91985\Desktop\123\Projects\ML\Waferfault_detection\env\lib\site-packages\joblib\externals\loky\_base.py", line 26, in _invoke_callbacks
    callback(self)
  File "c:\Users\91985\Desktop\123\Projects\ML\Waferfault_detection\env\lib\site-packages\joblib\parallel.py", line 814, in __call__
    self._dispatch_new()
  File "c:\Users\91985\Desktop\123\Projects\ML\Waferfault_detection\env\lib\site-packages\joblib\parallel.py", line 829, in _dispatch_new
    self.parallel.dispatch_next()
  File "c:\Users\91985\Desktop\123\Projects\ML\Waferfault_detection\env\lib\site-packages\joblib\parallel.py", line 1395, in dispatch_next
    if not self.dispatch_one_batch(self._original_iterator):
  File "c:\Users\91985\Desktop\123\Projects\ML\Waferfault_detection\env\lib\site-packages\joblib\parallel.py", line 1462, in dispatch_one_batch
    self._dispatch(tasks)
  File "c:\Users\91985\Desktop\123\Projects\ML\Waferfault_detection\env\lib\site-packages\joblib\parallel.py", line 1384, in _dispatch
    job = self._backend.apply_async(batch, callback=batch_tracker)
  File "c:\Users\91985\Desktop\123\Projects\ML\Waferfault_detection\env\lib\site-packages\joblib\_parallel_backends.py", line 600, in apply_async
    future = self._workers.submit(func)
  File "c:\Users\91985\Desktop\123\Projects\ML\Waferfault_detection\env\lib\site-packages\joblib\externals\loky\reusable_executor.py", line 225, in submit
    return super().submit(fn, *args, **kwargs)
  File "c:\Users\91985\Desktop\123\Projects\ML\Waferfault_detection\env\lib\site-packages\joblib\externals\loky\process_executor.py", line 1228, in submit
    raise ShutdownExecutorError(
joblib.externals.loky.process_executor.ShutdownExecutorError: cannot schedule new futures after shutdown
[ 2023-12-11 20:13:07,556 ] 28 concurrent.futures - ERROR - exception calling callback for <Future at 0x2037ed4ceb0 state=finished returned list>
Traceback (most recent call last):
  File "c:\Users\91985\Desktop\123\Projects\ML\Waferfault_detection\env\lib\site-packages\joblib\externals\loky\_base.py", line 26, in _invoke_callbacks
    callback(self)
  File "c:\Users\91985\Desktop\123\Projects\ML\Waferfault_detection\env\lib\site-packages\joblib\parallel.py", line 814, in __call__
    self._dispatch_new()
  File "c:\Users\91985\Desktop\123\Projects\ML\Waferfault_detection\env\lib\site-packages\joblib\parallel.py", line 829, in _dispatch_new
    self.parallel.dispatch_next()
  File "c:\Users\91985\Desktop\123\Projects\ML\Waferfault_detection\env\lib\site-packages\joblib\parallel.py", line 1395, in dispatch_next
    if not self.dispatch_one_batch(self._original_iterator):
  File "c:\Users\91985\Desktop\123\Projects\ML\Waferfault_detection\env\lib\site-packages\joblib\parallel.py", line 1462, in dispatch_one_batch
    self._dispatch(tasks)
  File "c:\Users\91985\Desktop\123\Projects\ML\Waferfault_detection\env\lib\site-packages\joblib\parallel.py", line 1384, in _dispatch
    job = self._backend.apply_async(batch, callback=batch_tracker)
  File "c:\Users\91985\Desktop\123\Projects\ML\Waferfault_detection\env\lib\site-packages\joblib\_parallel_backends.py", line 600, in apply_async
    future = self._workers.submit(func)
  File "c:\Users\91985\Desktop\123\Projects\ML\Waferfault_detection\env\lib\site-packages\joblib\externals\loky\reusable_executor.py", line 225, in submit
    return super().submit(fn, *args, **kwargs)
  File "c:\Users\91985\Desktop\123\Projects\ML\Waferfault_detection\env\lib\site-packages\joblib\externals\loky\process_executor.py", line 1228, in submit
    raise ShutdownExecutorError(
joblib.externals.loky.process_executor.ShutdownExecutorError: cannot schedule new futures after shutdown
[ 2023-12-11 20:13:07,919 ] 28 concurrent.futures - ERROR - exception calling callback for <Future at 0x2037ed4cd30 state=finished returned list>
Traceback (most recent call last):
  File "c:\Users\91985\Desktop\123\Projects\ML\Waferfault_detection\env\lib\site-packages\joblib\externals\loky\_base.py", line 26, in _invoke_callbacks
    callback(self)
  File "c:\Users\91985\Desktop\123\Projects\ML\Waferfault_detection\env\lib\site-packages\joblib\parallel.py", line 814, in __call__
    self._dispatch_new()
  File "c:\Users\91985\Desktop\123\Projects\ML\Waferfault_detection\env\lib\site-packages\joblib\parallel.py", line 829, in _dispatch_new
    self.parallel.dispatch_next()
  File "c:\Users\91985\Desktop\123\Projects\ML\Waferfault_detection\env\lib\site-packages\joblib\parallel.py", line 1395, in dispatch_next
    if not self.dispatch_one_batch(self._original_iterator):
  File "c:\Users\91985\Desktop\123\Projects\ML\Waferfault_detection\env\lib\site-packages\joblib\parallel.py", line 1462, in dispatch_one_batch
    self._dispatch(tasks)
  File "c:\Users\91985\Desktop\123\Projects\ML\Waferfault_detection\env\lib\site-packages\joblib\parallel.py", line 1384, in _dispatch
    job = self._backend.apply_async(batch, callback=batch_tracker)
  File "c:\Users\91985\Desktop\123\Projects\ML\Waferfault_detection\env\lib\site-packages\joblib\_parallel_backends.py", line 600, in apply_async
    future = self._workers.submit(func)
  File "c:\Users\91985\Desktop\123\Projects\ML\Waferfault_detection\env\lib\site-packages\joblib\externals\loky\reusable_executor.py", line 225, in submit
    return super().submit(fn, *args, **kwargs)
  File "c:\Users\91985\Desktop\123\Projects\ML\Waferfault_detection\env\lib\site-packages\joblib\externals\loky\process_executor.py", line 1228, in submit
    raise ShutdownExecutorError(
joblib.externals.loky.process_executor.ShutdownExecutorError: cannot schedule new futures after shutdown
[ 2023-12-11 20:13:07,967 ] 28 concurrent.futures - ERROR - exception calling callback for <Future at 0x2037ed48af0 state=finished returned list>
Traceback (most recent call last):
  File "c:\Users\91985\Desktop\123\Projects\ML\Waferfault_detection\env\lib\site-packages\joblib\externals\loky\_base.py", line 26, in _invoke_callbacks
    callback(self)
  File "c:\Users\91985\Desktop\123\Projects\ML\Waferfault_detection\env\lib\site-packages\joblib\parallel.py", line 814, in __call__
    self._dispatch_new()
  File "c:\Users\91985\Desktop\123\Projects\ML\Waferfault_detection\env\lib\site-packages\joblib\parallel.py", line 829, in _dispatch_new
    self.parallel.dispatch_next()
  File "c:\Users\91985\Desktop\123\Projects\ML\Waferfault_detection\env\lib\site-packages\joblib\parallel.py", line 1395, in dispatch_next
    if not self.dispatch_one_batch(self._original_iterator):
  File "c:\Users\91985\Desktop\123\Projects\ML\Waferfault_detection\env\lib\site-packages\joblib\parallel.py", line 1462, in dispatch_one_batch
    self._dispatch(tasks)
  File "c:\Users\91985\Desktop\123\Projects\ML\Waferfault_detection\env\lib\site-packages\joblib\parallel.py", line 1384, in _dispatch
    job = self._backend.apply_async(batch, callback=batch_tracker)
  File "c:\Users\91985\Desktop\123\Projects\ML\Waferfault_detection\env\lib\site-packages\joblib\_parallel_backends.py", line 600, in apply_async
    future = self._workers.submit(func)
  File "c:\Users\91985\Desktop\123\Projects\ML\Waferfault_detection\env\lib\site-packages\joblib\externals\loky\reusable_executor.py", line 225, in submit
    return super().submit(fn, *args, **kwargs)
  File "c:\Users\91985\Desktop\123\Projects\ML\Waferfault_detection\env\lib\site-packages\joblib\externals\loky\process_executor.py", line 1228, in submit
    raise ShutdownExecutorError(
joblib.externals.loky.process_executor.ShutdownExecutorError: cannot schedule new futures after shutdown
[ 2023-12-11 20:13:08,248 ] 28 concurrent.futures - ERROR - exception calling callback for <Future at 0x2037ed4c370 state=finished returned list>
Traceback (most recent call last):
  File "c:\Users\91985\Desktop\123\Projects\ML\Waferfault_detection\env\lib\site-packages\joblib\externals\loky\_base.py", line 26, in _invoke_callbacks
    callback(self)
  File "c:\Users\91985\Desktop\123\Projects\ML\Waferfault_detection\env\lib\site-packages\joblib\parallel.py", line 814, in __call__
    self._dispatch_new()
  File "c:\Users\91985\Desktop\123\Projects\ML\Waferfault_detection\env\lib\site-packages\joblib\parallel.py", line 829, in _dispatch_new
    self.parallel.dispatch_next()
  File "c:\Users\91985\Desktop\123\Projects\ML\Waferfault_detection\env\lib\site-packages\joblib\parallel.py", line 1395, in dispatch_next
    if not self.dispatch_one_batch(self._original_iterator):
  File "c:\Users\91985\Desktop\123\Projects\ML\Waferfault_detection\env\lib\site-packages\joblib\parallel.py", line 1462, in dispatch_one_batch
    self._dispatch(tasks)
  File "c:\Users\91985\Desktop\123\Projects\ML\Waferfault_detection\env\lib\site-packages\joblib\parallel.py", line 1384, in _dispatch
    job = self._backend.apply_async(batch, callback=batch_tracker)
  File "c:\Users\91985\Desktop\123\Projects\ML\Waferfault_detection\env\lib\site-packages\joblib\_parallel_backends.py", line 600, in apply_async
    future = self._workers.submit(func)
  File "c:\Users\91985\Desktop\123\Projects\ML\Waferfault_detection\env\lib\site-packages\joblib\externals\loky\reusable_executor.py", line 225, in submit
    return super().submit(fn, *args, **kwargs)
  File "c:\Users\91985\Desktop\123\Projects\ML\Waferfault_detection\env\lib\site-packages\joblib\externals\loky\process_executor.py", line 1228, in submit
    raise ShutdownExecutorError(
joblib.externals.loky.process_executor.ShutdownExecutorError: cannot schedule new futures after shutdown
[ 2023-12-11 20:13:09,091 ] 28 concurrent.futures - ERROR - exception calling callback for <Future at 0x2037ed488b0 state=finished returned list>
Traceback (most recent call last):
  File "c:\Users\91985\Desktop\123\Projects\ML\Waferfault_detection\env\lib\site-packages\joblib\externals\loky\_base.py", line 26, in _invoke_callbacks
    callback(self)
  File "c:\Users\91985\Desktop\123\Projects\ML\Waferfault_detection\env\lib\site-packages\joblib\parallel.py", line 814, in __call__
    self._dispatch_new()
  File "c:\Users\91985\Desktop\123\Projects\ML\Waferfault_detection\env\lib\site-packages\joblib\parallel.py", line 829, in _dispatch_new
    self.parallel.dispatch_next()
  File "c:\Users\91985\Desktop\123\Projects\ML\Waferfault_detection\env\lib\site-packages\joblib\parallel.py", line 1395, in dispatch_next
    if not self.dispatch_one_batch(self._original_iterator):
  File "c:\Users\91985\Desktop\123\Projects\ML\Waferfault_detection\env\lib\site-packages\joblib\parallel.py", line 1462, in dispatch_one_batch
    self._dispatch(tasks)
  File "c:\Users\91985\Desktop\123\Projects\ML\Waferfault_detection\env\lib\site-packages\joblib\parallel.py", line 1384, in _dispatch
    job = self._backend.apply_async(batch, callback=batch_tracker)
  File "c:\Users\91985\Desktop\123\Projects\ML\Waferfault_detection\env\lib\site-packages\joblib\_parallel_backends.py", line 600, in apply_async
    future = self._workers.submit(func)
  File "c:\Users\91985\Desktop\123\Projects\ML\Waferfault_detection\env\lib\site-packages\joblib\externals\loky\reusable_executor.py", line 225, in submit
    return super().submit(fn, *args, **kwargs)
  File "c:\Users\91985\Desktop\123\Projects\ML\Waferfault_detection\env\lib\site-packages\joblib\externals\loky\process_executor.py", line 1228, in submit
    raise ShutdownExecutorError(
joblib.externals.loky.process_executor.ShutdownExecutorError: cannot schedule new futures after shutdown
[ 2023-12-11 20:13:09,111 ] 28 concurrent.futures - ERROR - exception calling callback for <Future at 0x2037ed486d0 state=finished returned list>
Traceback (most recent call last):
  File "c:\Users\91985\Desktop\123\Projects\ML\Waferfault_detection\env\lib\site-packages\joblib\externals\loky\_base.py", line 26, in _invoke_callbacks
    callback(self)
  File "c:\Users\91985\Desktop\123\Projects\ML\Waferfault_detection\env\lib\site-packages\joblib\parallel.py", line 814, in __call__
    self._dispatch_new()
  File "c:\Users\91985\Desktop\123\Projects\ML\Waferfault_detection\env\lib\site-packages\joblib\parallel.py", line 829, in _dispatch_new
    self.parallel.dispatch_next()
  File "c:\Users\91985\Desktop\123\Projects\ML\Waferfault_detection\env\lib\site-packages\joblib\parallel.py", line 1395, in dispatch_next
    if not self.dispatch_one_batch(self._original_iterator):
  File "c:\Users\91985\Desktop\123\Projects\ML\Waferfault_detection\env\lib\site-packages\joblib\parallel.py", line 1462, in dispatch_one_batch
    self._dispatch(tasks)
  File "c:\Users\91985\Desktop\123\Projects\ML\Waferfault_detection\env\lib\site-packages\joblib\parallel.py", line 1384, in _dispatch
    job = self._backend.apply_async(batch, callback=batch_tracker)
  File "c:\Users\91985\Desktop\123\Projects\ML\Waferfault_detection\env\lib\site-packages\joblib\_parallel_backends.py", line 600, in apply_async
    future = self._workers.submit(func)
  File "c:\Users\91985\Desktop\123\Projects\ML\Waferfault_detection\env\lib\site-packages\joblib\externals\loky\reusable_executor.py", line 225, in submit
    return super().submit(fn, *args, **kwargs)
  File "c:\Users\91985\Desktop\123\Projects\ML\Waferfault_detection\env\lib\site-packages\joblib\externals\loky\process_executor.py", line 1228, in submit
    raise ShutdownExecutorError(
joblib.externals.loky.process_executor.ShutdownExecutorError: cannot schedule new futures after shutdown
[ 2023-12-11 20:13:09,592 ] 28 concurrent.futures - ERROR - exception calling callback for <Future at 0x203009840d0 state=finished returned list>
Traceback (most recent call last):
  File "c:\Users\91985\Desktop\123\Projects\ML\Waferfault_detection\env\lib\site-packages\joblib\externals\loky\_base.py", line 26, in _invoke_callbacks
    callback(self)
  File "c:\Users\91985\Desktop\123\Projects\ML\Waferfault_detection\env\lib\site-packages\joblib\parallel.py", line 814, in __call__
    self._dispatch_new()
  File "c:\Users\91985\Desktop\123\Projects\ML\Waferfault_detection\env\lib\site-packages\joblib\parallel.py", line 829, in _dispatch_new
    self.parallel.dispatch_next()
  File "c:\Users\91985\Desktop\123\Projects\ML\Waferfault_detection\env\lib\site-packages\joblib\parallel.py", line 1395, in dispatch_next
    if not self.dispatch_one_batch(self._original_iterator):
  File "c:\Users\91985\Desktop\123\Projects\ML\Waferfault_detection\env\lib\site-packages\joblib\parallel.py", line 1462, in dispatch_one_batch
    self._dispatch(tasks)
  File "c:\Users\91985\Desktop\123\Projects\ML\Waferfault_detection\env\lib\site-packages\joblib\parallel.py", line 1384, in _dispatch
    job = self._backend.apply_async(batch, callback=batch_tracker)
  File "c:\Users\91985\Desktop\123\Projects\ML\Waferfault_detection\env\lib\site-packages\joblib\_parallel_backends.py", line 600, in apply_async
    future = self._workers.submit(func)
  File "c:\Users\91985\Desktop\123\Projects\ML\Waferfault_detection\env\lib\site-packages\joblib\externals\loky\reusable_executor.py", line 225, in submit
    return super().submit(fn, *args, **kwargs)
  File "c:\Users\91985\Desktop\123\Projects\ML\Waferfault_detection\env\lib\site-packages\joblib\externals\loky\process_executor.py", line 1228, in submit
    raise ShutdownExecutorError(
joblib.externals.loky.process_executor.ShutdownExecutorError: cannot schedule new futures after shutdown
[ 2023-12-11 20:13:09,877 ] 28 concurrent.futures - ERROR - exception calling callback for <Future at 0x203009841f0 state=finished returned list>
Traceback (most recent call last):
  File "c:\Users\91985\Desktop\123\Projects\ML\Waferfault_detection\env\lib\site-packages\joblib\externals\loky\_base.py", line 26, in _invoke_callbacks
    callback(self)
  File "c:\Users\91985\Desktop\123\Projects\ML\Waferfault_detection\env\lib\site-packages\joblib\parallel.py", line 814, in __call__
    self._dispatch_new()
  File "c:\Users\91985\Desktop\123\Projects\ML\Waferfault_detection\env\lib\site-packages\joblib\parallel.py", line 829, in _dispatch_new
    self.parallel.dispatch_next()
  File "c:\Users\91985\Desktop\123\Projects\ML\Waferfault_detection\env\lib\site-packages\joblib\parallel.py", line 1395, in dispatch_next
    if not self.dispatch_one_batch(self._original_iterator):
  File "c:\Users\91985\Desktop\123\Projects\ML\Waferfault_detection\env\lib\site-packages\joblib\parallel.py", line 1462, in dispatch_one_batch
    self._dispatch(tasks)
  File "c:\Users\91985\Desktop\123\Projects\ML\Waferfault_detection\env\lib\site-packages\joblib\parallel.py", line 1384, in _dispatch
    job = self._backend.apply_async(batch, callback=batch_tracker)
  File "c:\Users\91985\Desktop\123\Projects\ML\Waferfault_detection\env\lib\site-packages\joblib\_parallel_backends.py", line 600, in apply_async
    future = self._workers.submit(func)
  File "c:\Users\91985\Desktop\123\Projects\ML\Waferfault_detection\env\lib\site-packages\joblib\externals\loky\reusable_executor.py", line 225, in submit
    return super().submit(fn, *args, **kwargs)
  File "c:\Users\91985\Desktop\123\Projects\ML\Waferfault_detection\env\lib\site-packages\joblib\externals\loky\process_executor.py", line 1228, in submit
    raise ShutdownExecutorError(
joblib.externals.loky.process_executor.ShutdownExecutorError: cannot schedule new futures after shutdown
[ 2023-12-11 20:13:09,892 ] 28 concurrent.futures - ERROR - exception calling callback for <Future at 0x203009842b0 state=finished returned list>
Traceback (most recent call last):
  File "c:\Users\91985\Desktop\123\Projects\ML\Waferfault_detection\env\lib\site-packages\joblib\externals\loky\_base.py", line 26, in _invoke_callbacks
    callback(self)
  File "c:\Users\91985\Desktop\123\Projects\ML\Waferfault_detection\env\lib\site-packages\joblib\parallel.py", line 814, in __call__
    self._dispatch_new()
  File "c:\Users\91985\Desktop\123\Projects\ML\Waferfault_detection\env\lib\site-packages\joblib\parallel.py", line 829, in _dispatch_new
    self.parallel.dispatch_next()
  File "c:\Users\91985\Desktop\123\Projects\ML\Waferfault_detection\env\lib\site-packages\joblib\parallel.py", line 1395, in dispatch_next
    if not self.dispatch_one_batch(self._original_iterator):
  File "c:\Users\91985\Desktop\123\Projects\ML\Waferfault_detection\env\lib\site-packages\joblib\parallel.py", line 1462, in dispatch_one_batch
    self._dispatch(tasks)
  File "c:\Users\91985\Desktop\123\Projects\ML\Waferfault_detection\env\lib\site-packages\joblib\parallel.py", line 1384, in _dispatch
    job = self._backend.apply_async(batch, callback=batch_tracker)
  File "c:\Users\91985\Desktop\123\Projects\ML\Waferfault_detection\env\lib\site-packages\joblib\_parallel_backends.py", line 600, in apply_async
    future = self._workers.submit(func)
  File "c:\Users\91985\Desktop\123\Projects\ML\Waferfault_detection\env\lib\site-packages\joblib\externals\loky\reusable_executor.py", line 225, in submit
    return super().submit(fn, *args, **kwargs)
  File "c:\Users\91985\Desktop\123\Projects\ML\Waferfault_detection\env\lib\site-packages\joblib\externals\loky\process_executor.py", line 1228, in submit
    raise ShutdownExecutorError(
joblib.externals.loky.process_executor.ShutdownExecutorError: cannot schedule new futures after shutdown
[ 2023-12-11 20:13:10,841 ] 28 concurrent.futures - ERROR - exception calling callback for <Future at 0x203009841c0 state=finished returned list>
Traceback (most recent call last):
  File "c:\Users\91985\Desktop\123\Projects\ML\Waferfault_detection\env\lib\site-packages\joblib\externals\loky\_base.py", line 26, in _invoke_callbacks
    callback(self)
  File "c:\Users\91985\Desktop\123\Projects\ML\Waferfault_detection\env\lib\site-packages\joblib\parallel.py", line 814, in __call__
    self._dispatch_new()
  File "c:\Users\91985\Desktop\123\Projects\ML\Waferfault_detection\env\lib\site-packages\joblib\parallel.py", line 829, in _dispatch_new
    self.parallel.dispatch_next()
  File "c:\Users\91985\Desktop\123\Projects\ML\Waferfault_detection\env\lib\site-packages\joblib\parallel.py", line 1395, in dispatch_next
    if not self.dispatch_one_batch(self._original_iterator):
  File "c:\Users\91985\Desktop\123\Projects\ML\Waferfault_detection\env\lib\site-packages\joblib\parallel.py", line 1462, in dispatch_one_batch
    self._dispatch(tasks)
  File "c:\Users\91985\Desktop\123\Projects\ML\Waferfault_detection\env\lib\site-packages\joblib\parallel.py", line 1384, in _dispatch
    job = self._backend.apply_async(batch, callback=batch_tracker)
  File "c:\Users\91985\Desktop\123\Projects\ML\Waferfault_detection\env\lib\site-packages\joblib\_parallel_backends.py", line 600, in apply_async
    future = self._workers.submit(func)
  File "c:\Users\91985\Desktop\123\Projects\ML\Waferfault_detection\env\lib\site-packages\joblib\externals\loky\reusable_executor.py", line 225, in submit
    return super().submit(fn, *args, **kwargs)
  File "c:\Users\91985\Desktop\123\Projects\ML\Waferfault_detection\env\lib\site-packages\joblib\externals\loky\process_executor.py", line 1228, in submit
    raise ShutdownExecutorError(
joblib.externals.loky.process_executor.ShutdownExecutorError: cannot schedule new futures after shutdown
